Workbook

Sheet Overview
B2: Name | C2: Amount | D2: Weight per piece (gr) | E2: Comment
B3: Brioche | C3: =SUMIFS(Orders!G:G,Orders!F:F,B3) -> 0 | D3: 250
B4: Stockdorf Sourdough | C4: =SUMIFS(Orders!G:G,Orders!F:F,B4) -> 0 | D4: 750
B5: Spelt Sourdough | C5: =SUMIFS(Orders!G:G,Orders!F:F,B5) -> 0 | D5: 750
B6: Rye & Wheat Sourdough | C6: =SUMIFS(Orders!G:G,Orders!F:F,B6) -> 0 | D6: 750
B7: Ciabatta Olive & Origano | C7: =SUMIFS(Orders!G:G,Orders!F:F,B7) -> 0 | D7: 300
B8: Ciabatta Naturale | C8: =SUMIFS(Orders!G:G,Orders!F:F,B8) -> 0 | D8: 300
B9: Focaccia Naturale | C9: =SUMIFS(Orders!G:G,Orders!F:F,B9) -> 0 | D9: 400
B10: Focaccia Pomodorini | C10: =SUMIFS(Orders!G:G,Orders!F:F,B10) -> 0 | D10: 400
B11: Baguette | C11: =SUMIFS(Orders!G:G,Orders!F:F,B11) -> 0 | D11: 350
B12: Pizzaballen (10x 252gr) | C12: 0 | D12: 252 | E12: LUMBONO
B13: Focaccia Fulvio (2x 30x40) | C13: 0 | D13: 1900 | E13: LUMBONO
B14: Brezen | C14: 0 | D14: 80 | E14: LUMBONO
B15: Baby brioche | C15: 0 | D15: 65 | E15: LUMBONO
B16: Bagels | C16: 0 | D16: 120 | E16: LUMBONO
B17: Frühstückssemmel | C17: 0 | D17: 85 | E17: LUMBONO
B18: Blechpizza (abends) (1 blech = 2x 252gr) | C18: 0 | D18: =2*252 -> 504 | E18: LUMBONO
B19: Brot | C19: 0 | D19: 750 | E19: LUMBONO
B20: Dinkelsemmel | C20: 0 | D20: 70 | E20: LUMBONO
C22: =SUM(C3:C20) -> 0

Sheet Kostprijs
B2: Tot. gewicht per stuk: | C2: 250 | D2: =VLOOKUP(Kostprijs!D3,Overview!$B:$D,3,0) -> #N/A | E2: =VLOOKUP(Kostprijs!E3,Overview!$B:$D,3,0) -> 300 | F2: 750 | G2: 750 | H2: 500 | I2: =VLOOKUP(Kostprijs!I3,Overview!$B:$D,3,0) -> 400 | J2: =VLOOKUP(Kostprijs!J3,Overview!$B:$D,3,0) -> 400 | K2: =VLOOKUP(Kostprijs!K3,Overview!$B:$D,3,0) -> #N/A | P2: Kostprijs/kg | Q2: =Q3/C2*1000 -> 2.47644 | R2: =R3/D2*1000 -> #N/A | S2: =S3/E2*1000 -> 1.1279933 | T2: =T3/F2*1000 -> 0 | U2: =U3/G2*1000 -> 1.0356533 | V2: =V3/H2*1000 -> 3.02302 | W2: =W3/I2*1000 -> 2.13865 | X2: =X3/J2*1000 -> 4.51165 | Y2: =Y3/K2*1000 -> #N/A
B3: Gewicht ingredient (gr) | C3: Big Brioche | D3: Ciabatta olive | E3: Ciabatta naturale | F3: Roggenmisch | G3: Stockdorf SD | H3: Seeded SD | I3: Focaccia naturale | J3: Focaccia pomodorini | P3: Kostprijs per stuk | Q3: =SUM(Q5:Q51) -> 0.61911 | R3: =SUM(R5:R51) -> 0.72303971 | S3: =SUM(S5:S51) -> 0.338398 | T3: =SUM(T5:T51) -> 0 | U3: =SUM(U5:U51) -> 0.77674 | V3: =SUM(V5:V51) -> 1.51151 | W3: =SUM(W5:W51) -> 0.85546 | X3: =SUM(X5:X51) -> 1.80466 | Y3: =SUM(Y5:Y51) -> 0
B4: Sum ingr. | C4: =SUM(C5:C51) -> 295 | D4: =SUM(D5:D51) -> 384.4 | E4: =SUM(E5:E51) -> 348 | F4: =SUM(F5:F51) -> 0 | G4: =SUM(G5:G51) -> 897.2 | H4: =SUM(H5:H51) -> 757.1 | I4: =SUM(I5:I51) -> 399 | J4: =SUM(J5:J51) -> 469 | K4: =SUM(K5:K51) -> 0 | M4: Sum | O4: Prijs/kg | Q4: =C3 -> Big Brioche | R4: =D3 -> Ciabatta olive | S4: =E3 -> Ciabatta naturale | T4: =F3 -> Roggenmisch | U4: =G3 -> Stockdorf SD | V4: =H3 -> Seeded SD | W4: =I3 -> Focaccia naturale | X4: =J3 -> Focaccia pomodorini | Y4: =K3 -> 0 | AA4: Sum
B5: Acerola poeder | D5: 0.1 | E5: 0.1 | G5: 0.2 | H5: 0.1 | M5: =SUM(C5:K5) -> 0.5 | O5: 98 | P5: =B5 -> Acerola poeder | Q5: =IFERROR($O5/1000*C5,0) -> 0 | R5: =IFERROR($O5/1000*D5,0) -> 0.0098 | S5: =IFERROR($O5/1000*E5,0) -> 0.0098 | T5: =IFERROR($O5/1000*F5,0) -> 0 | U5: =IFERROR($O5/1000*G5,0) -> 0.0196 | V5: =IFERROR($O5/1000*H5,0) -> 0.0098 | W5: =IFERROR($O5/1000*I5,0) -> 0 | X5: =IFERROR($O5/1000*J5,0) -> 0 | Y5: =IFERROR($O5/1000*K5,0) -> 0 | AA5: =SUM(Q5:Y5) -> 0.049
B6: Amandel (geschaafd) | C6: 3 | M6: =SUM(C6:K6) -> 3 | P6: =B6 -> Amandel (geschaafd) | Q6: =IFERROR($O6/1000*C6,0) -> 0 | R6: =IFERROR($O6/1000*D6,0) -> 0 | S6: =IFERROR($O6/1000*E6,0) -> 0 | T6: =IFERROR($O6/1000*F6,0) -> 0 | U6: =IFERROR($O6/1000*G6,0) -> 0 | V6: =IFERROR($O6/1000*H6,0) -> 0 | W6: =IFERROR($O6/1000*I6,0) -> 0 | X6: =IFERROR($O6/1000*J6,0) -> 0 | Y6: =IFERROR($O6/1000*K6,0) -> 0 | AA6: =SUM(Q6:Y6) -> 0
B7: Bakpoeder | M7: =SUM(C7:K7) -> 0 | O7: 17.44 | P7: =B7 -> Bakpoeder | Q7: =IFERROR($O7/1000*C7,0) -> 0 | R7: =IFERROR($O7/1000*D7,0) -> 0 | S7: =IFERROR($O7/1000*E7,0) -> 0 | T7: =IFERROR($O7/1000*F7,0) -> 0 | U7: =IFERROR($O7/1000*G7,0) -> 0 | V7: =IFERROR($O7/1000*H7,0) -> 0 | W7: =IFERROR($O7/1000*I7,0) -> 0 | X7: =IFERROR($O7/1000*J7,0) -> 0 | Y7: =IFERROR($O7/1000*K7,0) -> 0 | AA7: =SUM(Q7:Y7) -> 0
B8: Bio appels | M8: =SUM(C8:K8) -> 0 | O8: 4.49 | P8: =B8 -> Bio appels | Q8: =IFERROR($O8/1000*C8,0) -> 0 | R8: =IFERROR($O8/1000*D8,0) -> 0 | S8: =IFERROR($O8/1000*E8,0) -> 0 | T8: =IFERROR($O8/1000*F8,0) -> 0 | U8: =IFERROR($O8/1000*G8,0) -> 0 | V8: =IFERROR($O8/1000*H8,0) -> 0 | W8: =IFERROR($O8/1000*I8,0) -> 0 | X8: =IFERROR($O8/1000*J8,0) -> 0 | Y8: =IFERROR($O8/1000*K8,0) -> 0 | AA8: =SUM(Q8:Y8) -> 0
B9: Boter | C9: 32 | M9: =SUM(C9:K9) -> 32 | O9: 2.99 | P9: =B9 -> Boter | Q9: =IFERROR($O9/1000*C9,0) -> 0.09568 | R9: =IFERROR($O9/1000*D9,0) -> 0 | S9: =IFERROR($O9/1000*E9,0) -> 0 | T9: =IFERROR($O9/1000*F9,0) -> 0 | U9: =IFERROR($O9/1000*G9,0) -> 0 | V9: =IFERROR($O9/1000*H9,0) -> 0 | W9: =IFERROR($O9/1000*I9,0) -> 0 | X9: =IFERROR($O9/1000*J9,0) -> 0 | Y9: =IFERROR($O9/1000*K9,0) -> 0 | AA9: =SUM(Q9:Y9) -> 0.09568
B10: Cacaopoeder | M10: =SUM(C10:K10) -> 0 | O10: 35.92 | P10: =B10 -> Cacaopoeder | Q10: =IFERROR($O10/1000*C10,0) -> 0 | R10: =IFERROR($O10/1000*D10,0) -> 0 | S10: =IFERROR($O10/1000*E10,0) -> 0 | T10: =IFERROR($O10/1000*F10,0) -> 0 | U10: =IFERROR($O10/1000*G10,0) -> 0 | V10: =IFERROR($O10/1000*H10,0) -> 0 | W10: =IFERROR($O10/1000*I10,0) -> 0 | X10: =IFERROR($O10/1000*J10,0) -> 0 | Y10: =IFERROR($O10/1000*K10,0) -> 0 | AA10: =SUM(Q10:Y10) -> 0
B11: Ei | C11: 5 | M11: =SUM(C11:K11) -> 5 | O11: 8.6 | P11: =B11 -> Ei | Q11: =IFERROR($O11/1000*C11,0) -> 0.043 | R11: =IFERROR($O11/1000*D11,0) -> 0 | S11: =IFERROR($O11/1000*E11,0) -> 0 | T11: =IFERROR($O11/1000*F11,0) -> 0 | U11: =IFERROR($O11/1000*G11,0) -> 0 | V11: =IFERROR($O11/1000*H11,0) -> 0 | W11: =IFERROR($O11/1000*I11,0) -> 0 | X11: =IFERROR($O11/1000*J11,0) -> 0 | Y11: =IFERROR($O11/1000*K11,0) -> 0 | AA11: =SUM(Q11:Y11) -> 0.043
B12: Gist (vers) | C12: 4 | D12: 0.9 | E12: 0.9 | I12: 2 | J12: 2 | M12: =SUM(C12:K12) -> 9.8 | O12: 4.52 | P12: =B12 -> Gist (vers) | Q12: =IFERROR($O12/1000*C12,0) -> 0.01808 | R12: =IFERROR($O12/1000*D12,0) -> 0.004068 | S12: =IFERROR($O12/1000*E12,0) -> 0.004068 | T12: =IFERROR($O12/1000*F12,0) -> 0 | U12: =IFERROR($O12/1000*G12,0) -> 0 | V12: =IFERROR($O12/1000*H12,0) -> 0 | W12: =IFERROR($O12/1000*I12,0) -> 0.00904 | X12: =IFERROR($O12/1000*J12,0) -> 0.00904 | Y12: =IFERROR($O12/1000*K12,0) -> 0 | AA12: =SUM(Q12:Y12) -> 0.044296
B13: Hagelzucker | C13: 5 | M13: =SUM(C13:K13) -> 5 | O13: 3.65 | P13: =B13 -> Hagelzucker | Q13: =IFERROR($O13/1000*C13,0) -> 0.01825 | R13: =IFERROR($O13/1000*D13,0) -> 0 | S13: =IFERROR($O13/1000*E13,0) -> 0 | T13: =IFERROR($O13/1000*F13,0) -> 0 | U13: =IFERROR($O13/1000*G13,0) -> 0 | V13: =IFERROR($O13/1000*H13,0) -> 0 | W13: =IFERROR($O13/1000*I13,0) -> 0 | X13: =IFERROR($O13/1000*J13,0) -> 0 | Y13: =IFERROR($O13/1000*K13,0) -> 0 | AA13: =SUM(Q13:Y13) -> 0.01825
B14: Havervlokken | M14: =SUM(C14:K14) -> 0 | O14: 1.6 | P14: =B14 -> Havervlokken | Q14: =IFERROR($O14/1000*C14,0) -> 0 | R14: =IFERROR($O14/1000*D14,0) -> 0 | S14: =IFERROR($O14/1000*E14,0) -> 0 | T14: =IFERROR($O14/1000*F14,0) -> 0 | U14: =IFERROR($O14/1000*G14,0) -> 0 | V14: =IFERROR($O14/1000*H14,0) -> 0 | W14: =IFERROR($O14/1000*I14,0) -> 0 | X14: =IFERROR($O14/1000*J14,0) -> 0 | Y14: =IFERROR($O14/1000*K14,0) -> 0 | AA14: =SUM(Q14:Y14) -> 0
B15: Honing | M15: =SUM(C15:K15) -> 0 | O15: 10.8 | P15: =B15 -> Honing | Q15: =IFERROR($O15/1000*C15,0) -> 0 | R15: =IFERROR($O15/1000*D15,0) -> 0 | S15: =IFERROR($O15/1000*E15,0) -> 0 | T15: =IFERROR($O15/1000*F15,0) -> 0 | U15: =IFERROR($O15/1000*G15,0) -> 0 | V15: =IFERROR($O15/1000*H15,0) -> 0 | W15: =IFERROR($O15/1000*I15,0) -> 0 | X15: =IFERROR($O15/1000*J15,0) -> 0 | Y15: =IFERROR($O15/1000*K15,0) -> 0 | AA15: =SUM(Q15:Y15) -> 0
B16: Jus d'orange | M16: =SUM(C16:K16) -> 0 | O16: 3.19 | P16: =B16 -> Jus d'orange | Q16: =IFERROR($O16/1000*C16,0) -> 0 | R16: =IFERROR($O16/1000*D16,0) -> 0 | S16: =IFERROR($O16/1000*E16,0) -> 0 | T16: =IFERROR($O16/1000*F16,0) -> 0 | U16: =IFERROR($O16/1000*G16,0) -> 0 | V16: =IFERROR($O16/1000*H16,0) -> 0 | W16: =IFERROR($O16/1000*I16,0) -> 0 | X16: =IFERROR($O16/1000*J16,0) -> 0 | Y16: =IFERROR($O16/1000*K16,0) -> 0 | AA16: =SUM(Q16:Y16) -> 0
B17: Kaneel | M17: =SUM(C17:K17) -> 0 | O17: 22 | P17: =B17 -> Kaneel | Q17: =IFERROR($O17/1000*C17,0) -> 0 | R17: =IFERROR($O17/1000*D17,0) -> 0 | S17: =IFERROR($O17/1000*E17,0) -> 0 | T17: =IFERROR($O17/1000*F17,0) -> 0 | U17: =IFERROR($O17/1000*G17,0) -> 0 | V17: =IFERROR($O17/1000*H17,0) -> 0 | W17: =IFERROR($O17/1000*I17,0) -> 0 | X17: =IFERROR($O17/1000*J17,0) -> 0 | Y17: =IFERROR($O17/1000*K17,0) -> 0 | AA17: =SUM(Q17:Y17) -> 0
B18: Melk | C18: 65 | M18: =SUM(C18:K18) -> 65 | O18: 1.5 | P18: =B18 -> Melk | Q18: =IFERROR($O18/1000*C18,0) -> 0.0975 | R18: =IFERROR($O18/1000*D18,0) -> 0 | S18: =IFERROR($O18/1000*E18,0) -> 0 | T18: =IFERROR($O18/1000*F18,0) -> 0 | U18: =IFERROR($O18/1000*G18,0) -> 0 | V18: =IFERROR($O18/1000*H18,0) -> 0 | W18: =IFERROR($O18/1000*I18,0) -> 0 | X18: =IFERROR($O18/1000*J18,0) -> 0 | Y18: =IFERROR($O18/1000*K18,0) -> 0 | AA18: =SUM(Q18:Y18) -> 0.0975
B19: Olijfolie | D19: 3 | E19: 3 | I19: 50 | J19: 50 | M19: =SUM(C19:K19) -> 106 | O19: 10.99 | P19: =B19 -> Olijfolie | Q19: =IFERROR($O19/1000*C19,0) -> 0 | R19: =IFERROR($O19/1000*D19,0) -> 0.03297 | S19: =IFERROR($O19/1000*E19,0) -> 0.03297 | T19: =IFERROR($O19/1000*F19,0) -> 0 | U19: =IFERROR($O19/1000*G19,0) -> 0 | V19: =IFERROR($O19/1000*H19,0) -> 0 | W19: =IFERROR($O19/1000*I19,0) -> 0.5495 | X19: =IFERROR($O19/1000*J19,0) -> 0.5495 | Y19: =IFERROR($O19/1000*K19,0) -> 0 | AA19: =SUM(Q19:Y19) -> 1.16494
B20: Olijfringen (zwart) | D20: 36 | M20: =SUM(C20:K20) -> 36 | O20: =9.99/935*1000 -> 10.684492 | P20: =B20 -> Olijfringen (zwart) | Q20: =IFERROR($O20/1000*C20,0) -> 0 | R20: =IFERROR($O20/1000*D20,0) -> 0.38464171 | S20: =IFERROR($O20/1000*E20,0) -> 0 | T20: =IFERROR($O20/1000*F20,0) -> 0 | U20: =IFERROR($O20/1000*G20,0) -> 0 | V20: =IFERROR($O20/1000*H20,0) -> 0 | W20: =IFERROR($O20/1000*I20,0) -> 0 | X20: =IFERROR($O20/1000*J20,0) -> 0 | Y20: =IFERROR($O20/1000*K20,0) -> 0 | AA20: =SUM(Q20:Y20) -> 0.38464171
B21: Oregano (gedroogd) | D21: 0.4 | M21: =SUM(C21:K21) -> 0.4 | P21: =B21 -> Oregano (gedroogd) | Q21: =IFERROR($O21/1000*C21,0) -> 0 | R21: =IFERROR($O21/1000*D21,0) -> 0 | S21: =IFERROR($O21/1000*E21,0) -> 0 | T21: =IFERROR($O21/1000*F21,0) -> 0 | U21: =IFERROR($O21/1000*G21,0) -> 0 | V21: =IFERROR($O21/1000*H21,0) -> 0 | W21: =IFERROR($O21/1000*I21,0) -> 0 | X21: =IFERROR($O21/1000*J21,0) -> 0 | Y21: =IFERROR($O21/1000*K21,0) -> 0 | AA21: =SUM(Q21:Y21) -> 0
B22: Rogge T130/1150 | M22: =SUM(C22:K22) -> 0 | O22: 1.36 | P22: =B22 -> Rogge T130/1150 | Q22: =IFERROR($O22/1000*C22,0) -> 0 | R22: =IFERROR($O22/1000*D22,0) -> 0 | S22: =IFERROR($O22/1000*E22,0) -> 0 | T22: =IFERROR($O22/1000*F22,0) -> 0 | U22: =IFERROR($O22/1000*G22,0) -> 0 | V22: =IFERROR($O22/1000*H22,0) -> 0 | W22: =IFERROR($O22/1000*I22,0) -> 0 | X22: =IFERROR($O22/1000*J22,0) -> 0 | Y22: =IFERROR($O22/1000*K22,0) -> 0 | AA22: =SUM(Q22:Y22) -> 0
B23: Rogge T170/Vollkorn | M23: =SUM(C23:K23) -> 0 | O23: 1.96 | P23: =B23 -> Rogge T170/Vollkorn | Q23: =IFERROR($O23/1000*C23,0) -> 0 | R23: =IFERROR($O23/1000*D23,0) -> 0 | S23: =IFERROR($O23/1000*E23,0) -> 0 | T23: =IFERROR($O23/1000*F23,0) -> 0 | U23: =IFERROR($O23/1000*G23,0) -> 0 | V23: =IFERROR($O23/1000*H23,0) -> 0 | W23: =IFERROR($O23/1000*I23,0) -> 0 | X23: =IFERROR($O23/1000*J23,0) -> 0 | Y23: =IFERROR($O23/1000*K23,0) -> 0 | AA23: =SUM(Q23:Y23) -> 0
B24: Rogge T85/997 | M24: =SUM(C24:K24) -> 0 | O24: 1.36 | P24: =B24 -> Rogge T85/997 | Q24: =IFERROR($O24/1000*C24,0) -> 0 | R24: =IFERROR($O24/1000*D24,0) -> 0 | S24: =IFERROR($O24/1000*E24,0) -> 0 | T24: =IFERROR($O24/1000*F24,0) -> 0 | U24: =IFERROR($O24/1000*G24,0) -> 0 | V24: =IFERROR($O24/1000*H24,0) -> 0 | W24: =IFERROR($O24/1000*I24,0) -> 0 | X24: =IFERROR($O24/1000*J24,0) -> 0 | Y24: =IFERROR($O24/1000*K24,0) -> 0 | AA24: =SUM(Q24:Y24) -> 0
B25: Rozemarijn (gedroogd) | I25: 1 | J25: 1 | M25: =SUM(C25:K25) -> 2 | P25: =B25 -> Rozemarijn (gedroogd) | Q25: =IFERROR($O25/1000*C25,0) -> 0 | R25: =IFERROR($O25/1000*D25,0) -> 0 | S25: =IFERROR($O25/1000*E25,0) -> 0 | T25: =IFERROR($O25/1000*F25,0) -> 0 | U25: =IFERROR($O25/1000*G25,0) -> 0 | V25: =IFERROR($O25/1000*H25,0) -> 0 | W25: =IFERROR($O25/1000*I25,0) -> 0 | X25: =IFERROR($O25/1000*J25,0) -> 0 | Y25: =IFERROR($O25/1000*K25,0) -> 0 | AA25: =SUM(Q25:Y25) -> 0
B26: Rum | C26: 2 | M26: =SUM(C26:K26) -> 2 | O26: 10.7 | P26: =B26 -> Rum | Q26: =IFERROR($O26/1000*C26,0) -> 0.0214 | R26: =IFERROR($O26/1000*D26,0) -> 0 | S26: =IFERROR($O26/1000*E26,0) -> 0 | T26: =IFERROR($O26/1000*F26,0) -> 0 | U26: =IFERROR($O26/1000*G26,0) -> 0 | V26: =IFERROR($O26/1000*H26,0) -> 0 | W26: =IFERROR($O26/1000*I26,0) -> 0 | X26: =IFERROR($O26/1000*J26,0) -> 0 | Y26: =IFERROR($O26/1000*K26,0) -> 0 | AA26: =SUM(Q26:Y26) -> 0.0214
B27: Semola/Durum/Hartweizen | M27: =SUM(C27:K27) -> 0 | O27: 3.49 | P27: =B27 -> Semola/Durum/Hartweizen | Q27: =IFERROR($O27/1000*C27,0) -> 0 | R27: =IFERROR($O27/1000*D27,0) -> 0 | S27: =IFERROR($O27/1000*E27,0) -> 0 | T27: =IFERROR($O27/1000*F27,0) -> 0 | U27: =IFERROR($O27/1000*G27,0) -> 0 | V27: =IFERROR($O27/1000*H27,0) -> 0 | W27: =IFERROR($O27/1000*I27,0) -> 0 | X27: =IFERROR($O27/1000*J27,0) -> 0 | Y27: =IFERROR($O27/1000*K27,0) -> 0 | AA27: =SUM(Q27:Y27) -> 0
B28: Sesam (zwart) | M28: =SUM(C28:K28) -> 0 | O28: 8.41 | P28: =B28 -> Sesam (zwart) | Q28: =IFERROR($O28/1000*C28,0) -> 0 | R28: =IFERROR($O28/1000*D28,0) -> 0 | S28: =IFERROR($O28/1000*E28,0) -> 0 | T28: =IFERROR($O28/1000*F28,0) -> 0 | U28: =IFERROR($O28/1000*G28,0) -> 0 | V28: =IFERROR($O28/1000*H28,0) -> 0 | W28: =IFERROR($O28/1000*I28,0) -> 0 | X28: =IFERROR($O28/1000*J28,0) -> 0 | Y28: =IFERROR($O28/1000*K28,0) -> 0 | AA28: =SUM(Q28:Y28) -> 0
B29: Spelt T100/vollkorn | M29: =SUM(C29:K29) -> 0 | O29: 3.64 | P29: =B29 -> Spelt T100/vollkorn | Q29: =IFERROR($O29/1000*C29,0) -> 0 | R29: =IFERROR($O29/1000*D29,0) -> 0 | S29: =IFERROR($O29/1000*E29,0) -> 0 | T29: =IFERROR($O29/1000*F29,0) -> 0 | U29: =IFERROR($O29/1000*G29,0) -> 0 | V29: =IFERROR($O29/1000*H29,0) -> 0 | W29: =IFERROR($O29/1000*I29,0) -> 0 | X29: =IFERROR($O29/1000*J29,0) -> 0 | Y29: =IFERROR($O29/1000*K29,0) -> 0 | AA29: =SUM(Q29:Y29) -> 0
B30: Spelt T65/630 | C30: 8 | M30: =SUM(C30:K30) -> 8 | O30: 3.64 | P30: =B30 -> Spelt T65/630 | Q30: =IFERROR($O30/1000*C30,0) -> 0.02912 | R30: =IFERROR($O30/1000*D30,0) -> 0 | S30: =IFERROR($O30/1000*E30,0) -> 0 | T30: =IFERROR($O30/1000*F30,0) -> 0 | U30: =IFERROR($O30/1000*G30,0) -> 0 | V30: =IFERROR($O30/1000*H30,0) -> 0 | W30: =IFERROR($O30/1000*I30,0) -> 0 | X30: =IFERROR($O30/1000*J30,0) -> 0 | Y30: =IFERROR($O30/1000*K30,0) -> 0 | AA30: =SUM(Q30:Y30) -> 0.02912
B31: Suiker | C31: 16 | M31: =SUM(C31:K31) -> 16 | O31: 1.05 | P31: =B31 -> Suiker | Q31: =IFERROR($O31/1000*C31,0) -> 0.0168 | R31: =IFERROR($O31/1000*D31,0) -> 0 | S31: =IFERROR($O31/1000*E31,0) -> 0 | T31: =IFERROR($O31/1000*F31,0) -> 0 | U31: =IFERROR($O31/1000*G31,0) -> 0 | V31: =IFERROR($O31/1000*H31,0) -> 0 | W31: =IFERROR($O31/1000*I31,0) -> 0 | X31: =IFERROR($O31/1000*J31,0) -> 0 | Y31: =IFERROR($O31/1000*K31,0) -> 0 | AA31: =SUM(Q31:Y31) -> 0.0168
B32: Tarwe T150/volkoren | M32: =SUM(C32:K32) -> 0 | O32: 1.36 | P32: =B32 -> Tarwe T150/volkoren | Q32: =IFERROR($O32/1000*C32,0) -> 0 | R32: =IFERROR($O32/1000*D32,0) -> 0 | S32: =IFERROR($O32/1000*E32,0) -> 0 | T32: =IFERROR($O32/1000*F32,0) -> 0 | U32: =IFERROR($O32/1000*G32,0) -> 0 | V32: =IFERROR($O32/1000*H32,0) -> 0 | W32: =IFERROR($O32/1000*I32,0) -> 0 | X32: =IFERROR($O32/1000*J32,0) -> 0 | Y32: =IFERROR($O32/1000*K32,0) -> 0 | AA32: =SUM(Q32:Y32) -> 0
B33: Tarwe T45/405 | M33: =SUM(C33:K33) -> 0 | O33: 1.36 | P33: =B33 -> Tarwe T45/405 | Q33: =IFERROR($O33/1000*C33,0) -> 0 | R33: =IFERROR($O33/1000*D33,0) -> 0 | S33: =IFERROR($O33/1000*E33,0) -> 0 | T33: =IFERROR($O33/1000*F33,0) -> 0 | U33: =IFERROR($O33/1000*G33,0) -> 0 | V33: =IFERROR($O33/1000*H33,0) -> 0 | W33: =IFERROR($O33/1000*I33,0) -> 0 | X33: =IFERROR($O33/1000*J33,0) -> 0 | Y33: =IFERROR($O33/1000*K33,0) -> 0 | AA33: =SUM(Q33:Y33) -> 0
B34: Tarwe T65/550 | C34: 147 | D34: 28 | E34: 28 | M34: =SUM(C34:K34) -> 203 | O34: 1.36 | P34: =B34 -> Tarwe T65/550 | Q34: =IFERROR($O34/1000*C34,0) -> 0.19992 | R34: =IFERROR($O34/1000*D34,0) -> 0.03808 | S34: =IFERROR($O34/1000*E34,0) -> 0.03808 | T34: =IFERROR($O34/1000*F34,0) -> 0 | U34: =IFERROR($O34/1000*G34,0) -> 0 | V34: =IFERROR($O34/1000*H34,0) -> 0 | W34: =IFERROR($O34/1000*I34,0) -> 0 | X34: =IFERROR($O34/1000*J34,0) -> 0 | Y34: =IFERROR($O34/1000*K34,0) -> 0 | AA34: =SUM(Q34:Y34) -> 0.27608
B35: Tarwe T80/1050 | G35: 516 | H35: 363 | M35: =SUM(C35:K35) -> 879 | O35: 1.36 | P35: =B35 -> Tarwe T80/1050 | Q35: =IFERROR($O35/1000*C35,0) -> 0 | R35: =IFERROR($O35/1000*D35,0) -> 0 | S35: =IFERROR($O35/1000*E35,0) -> 0 | T35: =IFERROR($O35/1000*F35,0) -> 0 | U35: =IFERROR($O35/1000*G35,0) -> 0.70176 | V35: =IFERROR($O35/1000*H35,0) -> 0.49368 | W35: =IFERROR($O35/1000*I35,0) -> 0 | X35: =IFERROR($O35/1000*J35,0) -> 0 | Y35: =IFERROR($O35/1000*K35,0) -> 0 | AA35: =SUM(Q35:Y35) -> 1.19544
B36: Tarwe Tipo 0 | D36: 170 | E36: 170 | I36: 196 | J36: 196 | M36: =SUM(C36:K36) -> 732 | O36: 1.36 | P36: =B36 -> Tarwe Tipo 0 | Q36: =IFERROR($O36/1000*C36,0) -> 0 | R36: =IFERROR($O36/1000*D36,0) -> 0.2312 | S36: =IFERROR($O36/1000*E36,0) -> 0.2312 | T36: =IFERROR($O36/1000*F36,0) -> 0 | U36: =IFERROR($O36/1000*G36,0) -> 0 | V36: =IFERROR($O36/1000*H36,0) -> 0 | W36: =IFERROR($O36/1000*I36,0) -> 0.26656 | X36: =IFERROR($O36/1000*J36,0) -> 0.26656 | Y36: =IFERROR($O36/1000*K36,0) -> 0 | AA36: =SUM(Q36:Y36) -> 0.99552
B37: Tarwe Tipo 00 | M37: =SUM(C37:K37) -> 0 | O37: 1.36 | P37: =B37 -> Tarwe Tipo 00 | Q37: =IFERROR($O37/1000*C37,0) -> 0 | R37: =IFERROR($O37/1000*D37,0) -> 0 | S37: =IFERROR($O37/1000*E37,0) -> 0 | T37: =IFERROR($O37/1000*F37,0) -> 0 | U37: =IFERROR($O37/1000*G37,0) -> 0 | V37: =IFERROR($O37/1000*H37,0) -> 0 | W37: =IFERROR($O37/1000*I37,0) -> 0 | X37: =IFERROR($O37/1000*J37,0) -> 0 | Y37: =IFERROR($O37/1000*K37,0) -> 0 | AA37: =SUM(Q37:Y37) -> 0
B38: Tijd/extra | M38: =SUM(C38:K38) -> 0 | O38: 0.1 | P38: =B38 -> Tijd/extra | Q38: =IFERROR($O38/1000*C38,0) -> 0 | R38: =IFERROR($O38/1000*D38,0) -> 0 | S38: =IFERROR($O38/1000*E38,0) -> 0 | T38: =IFERROR($O38/1000*F38,0) -> 0 | U38: =IFERROR($O38/1000*G38,0) -> 0 | V38: =IFERROR($O38/1000*H38,0) -> 0 | W38: =IFERROR($O38/1000*I38,0) -> 0 | X38: =IFERROR($O38/1000*J38,0) -> 0 | Y38: =IFERROR($O38/1000*K38,0) -> 0 | AA38: =SUM(Q38:Y38) -> 0
B39: Vanillepasta | C39: 1 | M39: =SUM(C39:K39) -> 1 | O39: 73 | P39: =B39 -> Vanillepasta | Q39: =IFERROR($O39/1000*C39,0) -> 0.073 | R39: =IFERROR($O39/1000*D39,0) -> 0 | S39: =IFERROR($O39/1000*E39,0) -> 0 | T39: =IFERROR($O39/1000*F39,0) -> 0 | U39: =IFERROR($O39/1000*G39,0) -> 0 | V39: =IFERROR($O39/1000*H39,0) -> 0 | W39: =IFERROR($O39/1000*I39,0) -> 0 | X39: =IFERROR($O39/1000*J39,0) -> 0 | Y39: =IFERROR($O39/1000*K39,0) -> 0 | AA39: =SUM(Q39:Y39) -> 0.073
B40: Walnoten | M40: =SUM(C40:K40) -> 0 | O40: 17.95 | P40: =B40 -> Walnoten | Q40: =IFERROR($O40/1000*C40,0) -> 0 | R40: =IFERROR($O40/1000*D40,0) -> 0 | S40: =IFERROR($O40/1000*E40,0) -> 0 | T40: =IFERROR($O40/1000*F40,0) -> 0 | U40: =IFERROR($O40/1000*G40,0) -> 0 | V40: =IFERROR($O40/1000*H40,0) -> 0 | W40: =IFERROR($O40/1000*I40,0) -> 0 | X40: =IFERROR($O40/1000*J40,0) -> 0 | Y40: =IFERROR($O40/1000*K40,0) -> 0 | AA40: =SUM(Q40:Y40) -> 0
B41: Water | C41: 3 | D41: 142 | E41: 142 | G41: 372 | H41: 311 | I41: 142 | J41: 142 | M41: =SUM(C41:K41) -> 1254 | O41: 0.1 | P41: =B41 -> Water | Q41: =IFERROR($O41/1000*C41,0) -> 0.0003 | R41: =IFERROR($O41/1000*D41,0) -> 0.0142 | S41: =IFERROR($O41/1000*E41,0) -> 0.0142 | T41: =IFERROR($O41/1000*F41,0) -> 0 | U41: =IFERROR($O41/1000*G41,0) -> 0.0372 | V41: =IFERROR($O41/1000*H41,0) -> 0.0311 | W41: =IFERROR($O41/1000*I41,0) -> 0.0142 | X41: =IFERROR($O41/1000*J41,0) -> 0.0142 | Y41: =IFERROR($O41/1000*K41,0) -> 0 | AA41: =SUM(Q41:Y41) -> 0.1254
...

Sheet Prijslijst
E3: Alle Preise ohne MwSt. für Café Lumbono.
E4: 46006
D8: Brot (ca. 750gr) | E8: Semmel (ca. 80gr)
B9: Dinkel | C9: Dinkel(mischung) | D9: 6 | E9: 0.7
B10: Weizen/Roggen | C10: Weizen(mischung) | D10: 5 | E10: 0.6
C11: Weizen(mischung) mit Saaten/Kernen/Nüssen | D11: 6 | E11: 0.7
C12: Brezen | E12: 0.8
D14: Blech 40x60
B15: Pizza/Focaccia | C15: Focaccia | D15: 20
C16: Pizza | D16: 24
D18: ca. 750gr
B19: Süßes | C19: Marmorkuchen | D19: 8

Sheet Kostprijs LUMBONO
B2: Tot. gewicht per stuk: | C2: 250 | D2: =VLOOKUP('Kostprijs LUMBONO'!D3,Overview!$B:$D,3,0) -> 1900 | E2: =VLOOKUP('Kostprijs LUMBONO'!E3,Overview!$B:$D,3,0) -> 80 | F2: 750 | G2: 750 | H2: 500 | I2: =VLOOKUP('Kostprijs LUMBONO'!I3,Overview!$B:$D,3,0) -> #N/A | J2: =VLOOKUP('Kostprijs LUMBONO'!J3,Overview!$B:$D,3,0) -> #N/A | K2: =VLOOKUP('Kostprijs LUMBONO'!K3,Overview!$B:$D,3,0) -> #N/A | P2: Kostprijs/kg | Q2: =Q3/C2*1000 -> 0 | R2: =R3/D2*1000 -> 0 | S2: =S3/E2*1000 -> 0 | T2: =T3/F2*1000 -> 0 | U2: =U3/G2*1000 -> 0 | V2: =V3/H2*1000 -> 0 | W2: =W3/I2*1000 -> #N/A | X2: =X3/J2*1000 -> #N/A | Y2: =Y3/K2*1000 -> #N/A
B3: Gewicht ingredient (gr) | C3: Pizzaballen (5x 252gr) | D3: Focaccia Fulvio (2x 30x40) | E3: Brezen | P3: Kostprijs per stuk | Q3: =SUM(Q5:Q51) -> 0 | R3: =SUM(R5:R51) -> 0 | S3: =SUM(S5:S51) -> 0 | T3: =SUM(T5:T51) -> 0 | U3: =SUM(U5:U51) -> 0 | V3: =SUM(V5:V51) -> 0 | W3: =SUM(W5:W51) -> 0 | X3: =SUM(X5:X51) -> 0 | Y3: =SUM(Y5:Y51) -> 0
B4: Sum ingr. | C4: =SUM(C5:C51) -> 0 | D4: =SUM(D5:D51) -> 0 | E4: =SUM(E5:E51) -> 0 | F4: =SUM(F5:F51) -> 0 | G4: =SUM(G5:G51) -> 0 | H4: =SUM(H5:H51) -> 0 | I4: =SUM(I5:I51) -> 0 | J4: =SUM(J5:J51) -> 0 | K4: =SUM(K5:K51) -> 0 | M4: Sum | O4: Prijs/kg | Q4: =C3 -> Pizzaballen (5x 252gr) | R4: =D3 -> Focaccia Fulvio (2x 30x40) | S4: =E3 -> Brezen | T4: =F3 -> 0 | U4: =G3 -> 0 | V4: =H3 -> 0 | W4: =I3 -> 0 | X4: =J3 -> 0 | Y4: =K3 -> 0 | AA4: Sum
B5: Acerola poeder | M5: =SUM(C5:K5) -> 0 | O5: 98 | P5: =B5 -> Acerola poeder | Q5: =IFERROR($O5/1000*C5,0) -> 0 | R5: =IFERROR($O5/1000*D5,0) -> 0 | S5: =IFERROR($O5/1000*E5,0) -> 0 | T5: =IFERROR($O5/1000*F5,0) -> 0 | U5: =IFERROR($O5/1000*G5,0) -> 0 | V5: =IFERROR($O5/1000*H5,0) -> 0 | W5: =IFERROR($O5/1000*I5,0) -> 0 | X5: =IFERROR($O5/1000*J5,0) -> 0 | Y5: =IFERROR($O5/1000*K5,0) -> 0 | AA5: =SUM(Q5:Y5) -> 0
B6: Amandel (geschaafd) | M6: =SUM(C6:K6) -> 0 | P6: =B6 -> Amandel (geschaafd) | Q6: =IFERROR($O6/1000*C6,0) -> 0 | R6: =IFERROR($O6/1000*D6,0) -> 0 | S6: =IFERROR($O6/1000*E6,0) -> 0 | T6: =IFERROR($O6/1000*F6,0) -> 0 | U6: =IFERROR($O6/1000*G6,0) -> 0 | V6: =IFERROR($O6/1000*H6,0) -> 0 | W6: =IFERROR($O6/1000*I6,0) -> 0 | X6: =IFERROR($O6/1000*J6,0) -> 0 | Y6: =IFERROR($O6/1000*K6,0) -> 0 | AA6: =SUM(Q6:Y6) -> 0
B7: Bakpoeder | M7: =SUM(C7:K7) -> 0 | O7: 17.44 | P7: =B7 -> Bakpoeder | Q7: =IFERROR($O7/1000*C7,0) -> 0 | R7: =IFERROR($O7/1000*D7,0) -> 0 | S7: =IFERROR($O7/1000*E7,0) -> 0 | T7: =IFERROR($O7/1000*F7,0) -> 0 | U7: =IFERROR($O7/1000*G7,0) -> 0 | V7: =IFERROR($O7/1000*H7,0) -> 0 | W7: =IFERROR($O7/1000*I7,0) -> 0 | X7: =IFERROR($O7/1000*J7,0) -> 0 | Y7: =IFERROR($O7/1000*K7,0) -> 0 | AA7: =SUM(Q7:Y7) -> 0
B8: Bio appels | M8: =SUM(C8:K8) -> 0 | O8: 4.49 | P8: =B8 -> Bio appels | Q8: =IFERROR($O8/1000*C8,0) -> 0 | R8: =IFERROR($O8/1000*D8,0) -> 0 | S8: =IFERROR($O8/1000*E8,0) -> 0 | T8: =IFERROR($O8/1000*F8,0) -> 0 | U8: =IFERROR($O8/1000*G8,0) -> 0 | V8: =IFERROR($O8/1000*H8,0) -> 0 | W8: =IFERROR($O8/1000*I8,0) -> 0 | X8: =IFERROR($O8/1000*J8,0) -> 0 | Y8: =IFERROR($O8/1000*K8,0) -> 0 | AA8: =SUM(Q8:Y8) -> 0
B9: Boter | M9: =SUM(C9:K9) -> 0 | O9: 2.99 | P9: =B9 -> Boter | Q9: =IFERROR($O9/1000*C9,0) -> 0 | R9: =IFERROR($O9/1000*D9,0) -> 0 | S9: =IFERROR($O9/1000*E9,0) -> 0 | T9: =IFERROR($O9/1000*F9,0) -> 0 | U9: =IFERROR($O9/1000*G9,0) -> 0 | V9: =IFERROR($O9/1000*H9,0) -> 0 | W9: =IFERROR($O9/1000*I9,0) -> 0 | X9: =IFERROR($O9/1000*J9,0) -> 0 | Y9: =IFERROR($O9/1000*K9,0) -> 0 | AA9: =SUM(Q9:Y9) -> 0
B10: Cacaopoeder | M10: =SUM(C10:K10) -> 0 | O10: 35.92 | P10: =B10 -> Cacaopoeder | Q10: =IFERROR($O10/1000*C10,0) -> 0 | R10: =IFERROR($O10/1000*D10,0) -> 0 | S10: =IFERROR($O10/1000*E10,0) -> 0 | T10: =IFERROR($O10/1000*F10,0) -> 0 | U10: =IFERROR($O10/1000*G10,0) -> 0 | V10: =IFERROR($O10/1000*H10,0) -> 0 | W10: =IFERROR($O10/1000*I10,0) -> 0 | X10: =IFERROR($O10/1000*J10,0) -> 0 | Y10: =IFERROR($O10/1000*K10,0) -> 0 | AA10: =SUM(Q10:Y10) -> 0
B11: Ei | M11: =SUM(C11:K11) -> 0 | O11: 8.6 | P11: =B11 -> Ei | Q11: =IFERROR($O11/1000*C11,0) -> 0 | R11: =IFERROR($O11/1000*D11,0) -> 0 | S11: =IFERROR($O11/1000*E11,0) -> 0 | T11: =IFERROR($O11/1000*F11,0) -> 0 | U11: =IFERROR($O11/1000*G11,0) -> 0 | V11: =IFERROR($O11/1000*H11,0) -> 0 | W11: =IFERROR($O11/1000*I11,0) -> 0 | X11: =IFERROR($O11/1000*J11,0) -> 0 | Y11: =IFERROR($O11/1000*K11,0) -> 0 | AA11: =SUM(Q11:Y11) -> 0
B12: Gist (vers) | M12: =SUM(C12:K12) -> 0 | O12: 4.52 | P12: =B12 -> Gist (vers) | Q12: =IFERROR($O12/1000*C12,0) -> 0 | R12: =IFERROR($O12/1000*D12,0) -> 0 | S12: =IFERROR($O12/1000*E12,0) -> 0 | T12: =IFERROR($O12/1000*F12,0) -> 0 | U12: =IFERROR($O12/1000*G12,0) -> 0 | V12: =IFERROR($O12/1000*H12,0) -> 0 | W12: =IFERROR($O12/1000*I12,0) -> 0 | X12: =IFERROR($O12/1000*J12,0) -> 0 | Y12: =IFERROR($O12/1000*K12,0) -> 0 | AA12: =SUM(Q12:Y12) -> 0
B13: Hagelzucker | M13: =SUM(C13:K13) -> 0 | O13: 3.65 | P13: =B13 -> Hagelzucker | Q13: =IFERROR($O13/1000*C13,0) -> 0 | R13: =IFERROR($O13/1000*D13,0) -> 0 | S13: =IFERROR($O13/1000*E13,0) -> 0 | T13: =IFERROR($O13/1000*F13,0) -> 0 | U13: =IFERROR($O13/1000*G13,0) -> 0 | V13: =IFERROR($O13/1000*H13,0) -> 0 | W13: =IFERROR($O13/1000*I13,0) -> 0 | X13: =IFERROR($O13/1000*J13,0) -> 0 | Y13: =IFERROR($O13/1000*K13,0) -> 0 | AA13: =SUM(Q13:Y13) -> 0
B14: Havervlokken | M14: =SUM(C14:K14) -> 0 | O14: 1.6 | P14: =B14 -> Havervlokken | Q14: =IFERROR($O14/1000*C14,0) -> 0 | R14: =IFERROR($O14/1000*D14,0) -> 0 | S14: =IFERROR($O14/1000*E14,0) -> 0 | T14: =IFERROR($O14/1000*F14,0) -> 0 | U14: =IFERROR($O14/1000*G14,0) -> 0 | V14: =IFERROR($O14/1000*H14,0) -> 0 | W14: =IFERROR($O14/1000*I14,0) -> 0 | X14: =IFERROR($O14/1000*J14,0) -> 0 | Y14: =IFERROR($O14/1000*K14,0) -> 0 | AA14: =SUM(Q14:Y14) -> 0
B15: Honing | M15: =SUM(C15:K15) -> 0 | O15: 10.8 | P15: =B15 -> Honing | Q15: =IFERROR($O15/1000*C15,0) -> 0 | R15: =IFERROR($O15/1000*D15,0) -> 0 | S15: =IFERROR($O15/1000*E15,0) -> 0 | T15: =IFERROR($O15/1000*F15,0) -> 0 | U15: =IFERROR($O15/1000*G15,0) -> 0 | V15: =IFERROR($O15/1000*H15,0) -> 0 | W15: =IFERROR($O15/1000*I15,0) -> 0 | X15: =IFERROR($O15/1000*J15,0) -> 0 | Y15: =IFERROR($O15/1000*K15,0) -> 0 | AA15: =SUM(Q15:Y15) -> 0
B16: Jus d'orange | M16: =SUM(C16:K16) -> 0 | O16: 3.19 | P16: =B16 -> Jus d'orange | Q16: =IFERROR($O16/1000*C16,0) -> 0 | R16: =IFERROR($O16/1000*D16,0) -> 0 | S16: =IFERROR($O16/1000*E16,0) -> 0 | T16: =IFERROR($O16/1000*F16,0) -> 0 | U16: =IFERROR($O16/1000*G16,0) -> 0 | V16: =IFERROR($O16/1000*H16,0) -> 0 | W16: =IFERROR($O16/1000*I16,0) -> 0 | X16: =IFERROR($O16/1000*J16,0) -> 0 | Y16: =IFERROR($O16/1000*K16,0) -> 0 | AA16: =SUM(Q16:Y16) -> 0
B17: Kaneel | M17: =SUM(C17:K17) -> 0 | O17: 22 | P17: =B17 -> Kaneel | Q17: =IFERROR($O17/1000*C17,0) -> 0 | R17: =IFERROR($O17/1000*D17,0) -> 0 | S17: =IFERROR($O17/1000*E17,0) -> 0 | T17: =IFERROR($O17/1000*F17,0) -> 0 | U17: =IFERROR($O17/1000*G17,0) -> 0 | V17: =IFERROR($O17/1000*H17,0) -> 0 | W17: =IFERROR($O17/1000*I17,0) -> 0 | X17: =IFERROR($O17/1000*J17,0) -> 0 | Y17: =IFERROR($O17/1000*K17,0) -> 0 | AA17: =SUM(Q17:Y17) -> 0
B18: Melk | M18: =SUM(C18:K18) -> 0 | O18: 1.5 | P18: =B18 -> Melk | Q18: =IFERROR($O18/1000*C18,0) -> 0 | R18: =IFERROR($O18/1000*D18,0) -> 0 | S18: =IFERROR($O18/1000*E18,0) -> 0 | T18: =IFERROR($O18/1000*F18,0) -> 0 | U18: =IFERROR($O18/1000*G18,0) -> 0 | V18: =IFERROR($O18/1000*H18,0) -> 0 | W18: =IFERROR($O18/1000*I18,0) -> 0 | X18: =IFERROR($O18/1000*J18,0) -> 0 | Y18: =IFERROR($O18/1000*K18,0) -> 0 | AA18: =SUM(Q18:Y18) -> 0
B19: Olijfolie | M19: =SUM(C19:K19) -> 0 | O19: 10.99 | P19: =B19 -> Olijfolie | Q19: =IFERROR($O19/1000*C19,0) -> 0 | R19: =IFERROR($O19/1000*D19,0) -> 0 | S19: =IFERROR($O19/1000*E19,0) -> 0 | T19: =IFERROR($O19/1000*F19,0) -> 0 | U19: =IFERROR($O19/1000*G19,0) -> 0 | V19: =IFERROR($O19/1000*H19,0) -> 0 | W19: =IFERROR($O19/1000*I19,0) -> 0 | X19: =IFERROR($O19/1000*J19,0) -> 0 | Y19: =IFERROR($O19/1000*K19,0) -> 0 | AA19: =SUM(Q19:Y19) -> 0
B20: Olijfringen (zwart) | M20: =SUM(C20:K20) -> 0 | O20: =9.99/935*1000 -> 10.684492 | P20: =B20 -> Olijfringen (zwart) | Q20: =IFERROR($O20/1000*C20,0) -> 0 | R20: =IFERROR($O20/1000*D20,0) -> 0 | S20: =IFERROR($O20/1000*E20,0) -> 0 | T20: =IFERROR($O20/1000*F20,0) -> 0 | U20: =IFERROR($O20/1000*G20,0) -> 0 | V20: =IFERROR($O20/1000*H20,0) -> 0 | W20: =IFERROR($O20/1000*I20,0) -> 0 | X20: =IFERROR($O20/1000*J20,0) -> 0 | Y20: =IFERROR($O20/1000*K20,0) -> 0 | AA20: =SUM(Q20:Y20) -> 0
B21: Oregano (gedroogd) | M21: =SUM(C21:K21) -> 0 | P21: =B21 -> Oregano (gedroogd) | Q21: =IFERROR($O21/1000*C21,0) -> 0 | R21: =IFERROR($O21/1000*D21,0) -> 0 | S21: =IFERROR($O21/1000*E21,0) -> 0 | T21: =IFERROR($O21/1000*F21,0) -> 0 | U21: =IFERROR($O21/1000*G21,0) -> 0 | V21: =IFERROR($O21/1000*H21,0) -> 0 | W21: =IFERROR($O21/1000*I21,0) -> 0 | X21: =IFERROR($O21/1000*J21,0) -> 0 | Y21: =IFERROR($O21/1000*K21,0) -> 0 | AA21: =SUM(Q21:Y21) -> 0
B22: Rogge T130/1150 | M22: =SUM(C22:K22) -> 0 | O22: 1.36 | P22: =B22 -> Rogge T130/1150 | Q22: =IFERROR($O22/1000*C22,0) -> 0 | R22: =IFERROR($O22/1000*D22,0) -> 0 | S22: =IFERROR($O22/1000*E22,0) -> 0 | T22: =IFERROR($O22/1000*F22,0) -> 0 | U22: =IFERROR($O22/1000*G22,0) -> 0 | V22: =IFERROR($O22/1000*H22,0) -> 0 | W22: =IFERROR($O22/1000*I22,0) -> 0 | X22: =IFERROR($O22/1000*J22,0) -> 0 | Y22: =IFERROR($O22/1000*K22,0) -> 0 | AA22: =SUM(Q22:Y22) -> 0
B23: Rogge T170/Vollkorn | M23: =SUM(C23:K23) -> 0 | O23: 1.96 | P23: =B23 -> Rogge T170/Vollkorn | Q23: =IFERROR($O23/1000*C23,0) -> 0 | R23: =IFERROR($O23/1000*D23,0) -> 0 | S23: =IFERROR($O23/1000*E23,0) -> 0 | T23: =IFERROR($O23/1000*F23,0) -> 0 | U23: =IFERROR($O23/1000*G23,0) -> 0 | V23: =IFERROR($O23/1000*H23,0) -> 0 | W23: =IFERROR($O23/1000*I23,0) -> 0 | X23: =IFERROR($O23/1000*J23,0) -> 0 | Y23: =IFERROR($O23/1000*K23,0) -> 0 | AA23: =SUM(Q23:Y23) -> 0
B24: Rogge T85/997 | M24: =SUM(C24:K24) -> 0 | O24: 1.36 | P24: =B24 -> Rogge T85/997 | Q24: =IFERROR($O24/1000*C24,0) -> 0 | R24: =IFERROR($O24/1000*D24,0) -> 0 | S24: =IFERROR($O24/1000*E24,0) -> 0 | T24: =IFERROR($O24/1000*F24,0) -> 0 | U24: =IFERROR($O24/1000*G24,0) -> 0 | V24: =IFERROR($O24/1000*H24,0) -> 0 | W24: =IFERROR($O24/1000*I24,0) -> 0 | X24: =IFERROR($O24/1000*J24,0) -> 0 | Y24: =IFERROR($O24/1000*K24,0) -> 0 | AA24: =SUM(Q24:Y24) -> 0
B25: Rozemarijn (gedroogd) | M25: =SUM(C25:K25) -> 0 | P25: =B25 -> Rozemarijn (gedroogd) | Q25: =IFERROR($O25/1000*C25,0) -> 0 | R25: =IFERROR($O25/1000*D25,0) -> 0 | S25: =IFERROR($O25/1000*E25,0) -> 0 | T25: =IFERROR($O25/1000*F25,0) -> 0 | U25: =IFERROR($O25/1000*G25,0) -> 0 | V25: =IFERROR($O25/1000*H25,0) -> 0 | W25: =IFERROR($O25/1000*I25,0) -> 0 | X25: =IFERROR($O25/1000*J25,0) -> 0 | Y25: =IFERROR($O25/1000*K25,0) -> 0 | AA25: =SUM(Q25:Y25) -> 0
B26: Rum | M26: =SUM(C26:K26) -> 0 | O26: 10.7 | P26: =B26 -> Rum | Q26: =IFERROR($O26/1000*C26,0) -> 0 | R26: =IFERROR($O26/1000*D26,0) -> 0 | S26: =IFERROR($O26/1000*E26,0) -> 0 | T26: =IFERROR($O26/1000*F26,0) -> 0 | U26: =IFERROR($O26/1000*G26,0) -> 0 | V26: =IFERROR($O26/1000*H26,0) -> 0 | W26: =IFERROR($O26/1000*I26,0) -> 0 | X26: =IFERROR($O26/1000*J26,0) -> 0 | Y26: =IFERROR($O26/1000*K26,0) -> 0 | AA26: =SUM(Q26:Y26) -> 0
B27: Semola/Durum/Hartweizen | M27: =SUM(C27:K27) -> 0 | O27: 3.49 | P27: =B27 -> Semola/Durum/Hartweizen | Q27: =IFERROR($O27/1000*C27,0) -> 0 | R27: =IFERROR($O27/1000*D27,0) -> 0 | S27: =IFERROR($O27/1000*E27,0) -> 0 | T27: =IFERROR($O27/1000*F27,0) -> 0 | U27: =IFERROR($O27/1000*G27,0) -> 0 | V27: =IFERROR($O27/1000*H27,0) -> 0 | W27: =IFERROR($O27/1000*I27,0) -> 0 | X27: =IFERROR($O27/1000*J27,0) -> 0 | Y27: =IFERROR($O27/1000*K27,0) -> 0 | AA27: =SUM(Q27:Y27) -> 0
B28: Sesam (zwart) | M28: =SUM(C28:K28) -> 0 | O28: 8.41 | P28: =B28 -> Sesam (zwart) | Q28: =IFERROR($O28/1000*C28,0) -> 0 | R28: =IFERROR($O28/1000*D28,0) -> 0 | S28: =IFERROR($O28/1000*E28,0) -> 0 | T28: =IFERROR($O28/1000*F28,0) -> 0 | U28: =IFERROR($O28/1000*G28,0) -> 0 | V28: =IFERROR($O28/1000*H28,0) -> 0 | W28: =IFERROR($O28/1000*I28,0) -> 0 | X28: =IFERROR($O28/1000*J28,0) -> 0 | Y28: =IFERROR($O28/1000*K28,0) -> 0 | AA28: =SUM(Q28:Y28) -> 0
B29: Spelt T100/vollkorn | M29: =SUM(C29:K29) -> 0 | O29: 3.64 | P29: =B29 -> Spelt T100/vollkorn | Q29: =IFERROR($O29/1000*C29,0) -> 0 | R29: =IFERROR($O29/1000*D29,0) -> 0 | S29: =IFERROR($O29/1000*E29,0) -> 0 | T29: =IFERROR($O29/1000*F29,0) -> 0 | U29: =IFERROR($O29/1000*G29,0) -> 0 | V29: =IFERROR($O29/1000*H29,0) -> 0 | W29: =IFERROR($O29/1000*I29,0) -> 0 | X29: =IFERROR($O29/1000*J29,0) -> 0 | Y29: =IFERROR($O29/1000*K29,0) -> 0 | AA29: =SUM(Q29:Y29) -> 0
B30: Spelt T65/630 | M30: =SUM(C30:K30) -> 0 | O30: 3.64 | P30: =B30 -> Spelt T65/630 | Q30: =IFERROR($O30/1000*C30,0) -> 0 | R30: =IFERROR($O30/1000*D30,0) -> 0 | S30: =IFERROR($O30/1000*E30,0) -> 0 | T30: =IFERROR($O30/1000*F30,0) -> 0 | U30: =IFERROR($O30/1000*G30,0) -> 0 | V30: =IFERROR($O30/1000*H30,0) -> 0 | W30: =IFERROR($O30/1000*I30,0) -> 0 | X30: =IFERROR($O30/1000*J30,0) -> 0 | Y30: =IFERROR($O30/1000*K30,0) -> 0 | AA30: =SUM(Q30:Y30) -> 0
B31: Suiker | M31: =SUM(C31:K31) -> 0 | O31: 1.05 | P31: =B31 -> Suiker | Q31: =IFERROR($O31/1000*C31,0) -> 0 | R31: =IFERROR($O31/1000*D31,0) -> 0 | S31: =IFERROR($O31/1000*E31,0) -> 0 | T31: =IFERROR($O31/1000*F31,0) -> 0 | U31: =IFERROR($O31/1000*G31,0) -> 0 | V31: =IFERROR($O31/1000*H31,0) -> 0 | W31: =IFERROR($O31/1000*I31,0) -> 0 | X31: =IFERROR($O31/1000*J31,0) -> 0 | Y31: =IFERROR($O31/1000*K31,0) -> 0 | AA31: =SUM(Q31:Y31) -> 0
B32: Tarwe T150/volkoren | M32: =SUM(C32:K32) -> 0 | O32: 1.36 | P32: =B32 -> Tarwe T150/volkoren | Q32: =IFERROR($O32/1000*C32,0) -> 0 | R32: =IFERROR($O32/1000*D32,0) -> 0 | S32: =IFERROR($O32/1000*E32,0) -> 0 | T32: =IFERROR($O32/1000*F32,0) -> 0 | U32: =IFERROR($O32/1000*G32,0) -> 0 | V32: =IFERROR($O32/1000*H32,0) -> 0 | W32: =IFERROR($O32/1000*I32,0) -> 0 | X32: =IFERROR($O32/1000*J32,0) -> 0 | Y32: =IFERROR($O32/1000*K32,0) -> 0 | AA32: =SUM(Q32:Y32) -> 0
B33: Tarwe T45/405 | M33: =SUM(C33:K33) -> 0 | O33: 1.36 | P33: =B33 -> Tarwe T45/405 | Q33: =IFERROR($O33/1000*C33,0) -> 0 | R33: =IFERROR($O33/1000*D33,0) -> 0 | S33: =IFERROR($O33/1000*E33,0) -> 0 | T33: =IFERROR($O33/1000*F33,0) -> 0 | U33: =IFERROR($O33/1000*G33,0) -> 0 | V33: =IFERROR($O33/1000*H33,0) -> 0 | W33: =IFERROR($O33/1000*I33,0) -> 0 | X33: =IFERROR($O33/1000*J33,0) -> 0 | Y33: =IFERROR($O33/1000*K33,0) -> 0 | AA33: =SUM(Q33:Y33) -> 0
B34: Tarwe T65/550 | M34: =SUM(C34:K34) -> 0 | O34: 1.36 | P34: =B34 -> Tarwe T65/550 | Q34: =IFERROR($O34/1000*C34,0) -> 0 | R34: =IFERROR($O34/1000*D34,0) -> 0 | S34: =IFERROR($O34/1000*E34,0) -> 0 | T34: =IFERROR($O34/1000*F34,0) -> 0 | U34: =IFERROR($O34/1000*G34,0) -> 0 | V34: =IFERROR($O34/1000*H34,0) -> 0 | W34: =IFERROR($O34/1000*I34,0) -> 0 | X34: =IFERROR($O34/1000*J34,0) -> 0 | Y34: =IFERROR($O34/1000*K34,0) -> 0 | AA34: =SUM(Q34:Y34) -> 0
B35: Tarwe T80/1050 | M35: =SUM(C35:K35) -> 0 | O35: 1.36 | P35: =B35 -> Tarwe T80/1050 | Q35: =IFERROR($O35/1000*C35,0) -> 0 | R35: =IFERROR($O35/1000*D35,0) -> 0 | S35: =IFERROR($O35/1000*E35,0) -> 0 | T35: =IFERROR($O35/1000*F35,0) -> 0 | U35: =IFERROR($O35/1000*G35,0) -> 0 | V35: =IFERROR($O35/1000*H35,0) -> 0 | W35: =IFERROR($O35/1000*I35,0) -> 0 | X35: =IFERROR($O35/1000*J35,0) -> 0 | Y35: =IFERROR($O35/1000*K35,0) -> 0 | AA35: =SUM(Q35:Y35) -> 0
B36: Tarwe Tipo 0 | M36: =SUM(C36:K36) -> 0 | O36: 1.36 | P36: =B36 -> Tarwe Tipo 0 | Q36: =IFERROR($O36/1000*C36,0) -> 0 | R36: =IFERROR($O36/1000*D36,0) -> 0 | S36: =IFERROR($O36/1000*E36,0) -> 0 | T36: =IFERROR($O36/1000*F36,0) -> 0 | U36: =IFERROR($O36/1000*G36,0) -> 0 | V36: =IFERROR($O36/1000*H36,0) -> 0 | W36: =IFERROR($O36/1000*I36,0) -> 0 | X36: =IFERROR($O36/1000*J36,0) -> 0 | Y36: =IFERROR($O36/1000*K36,0) -> 0 | AA36: =SUM(Q36:Y36) -> 0
B37: Tarwe Tipo 00 | M37: =SUM(C37:K37) -> 0 | O37: 1.36 | P37: =B37 -> Tarwe Tipo 00 | Q37: =IFERROR($O37/1000*C37,0) -> 0 | R37: =IFERROR($O37/1000*D37,0) -> 0 | S37: =IFERROR($O37/1000*E37,0) -> 0 | T37: =IFERROR($O37/1000*F37,0) -> 0 | U37: =IFERROR($O37/1000*G37,0) -> 0 | V37: =IFERROR($O37/1000*H37,0) -> 0 | W37: =IFERROR($O37/1000*I37,0) -> 0 | X37: =IFERROR($O37/1000*J37,0) -> 0 | Y37: =IFERROR($O37/1000*K37,0) -> 0 | AA37: =SUM(Q37:Y37) -> 0
... B43: Zadenmelange | M43: =SUM(C43:K43) -> 0 | O43: 12.53 | P43: =B43 -> Zadenmelange | Q43: =IFERROR($O43/1000*C43,0) -> 0 | R43: =IFERROR($O43/1000*D43,0) -> 0 | S43: =IFERROR($O43/1000*E43,0) -> 0 | T43: =IFERROR($O43/1000*F43,0) -> 0 | U43: =IFERROR($O43/1000*G43,0) -> 0 | V43: =IFERROR($O43/1000*H43,0) -> 0 | W43: =IFERROR($O43/1000*I43,0) -> 0 | X43: =IFERROR($O43/1000*J43,0) -> 0 | Y43: =IFERROR($O43/1000*K43,0) -> 0 | AA43: =SUM(Q43:Y43) -> 0
B44: Zitronepasta | M44: =SUM(C44:K44) -> 0 | P44: =B44 -> Zitronepasta | Q44: =IFERROR($O44/1000*C44,0) -> 0 | R44: =IFERROR($O44/1000*D44,0) -> 0 | S44: =IFERROR($O44/1000*E44,0) -> 0 | T44: =IFERROR($O44/1000*F44,0) -> 0 | U44: =IFERROR($O44/1000*G44,0) -> 0 | V44: =IFERROR($O44/1000*H44,0) -> 0 | W44: =IFERROR($O44/1000*I44,0) -> 0 | X44: =IFERROR($O44/1000*J44,0) -> 0 | Y44: =IFERROR($O44/1000*K44,0) -> 0 | AA44: =SUM(Q44:Y44) -> 0
B45: Zout | M45: =SUM(C45:K45) -> 0 | O45: 2.02 | P45: =B45 -> Zout | Q45: =IFERROR($O45/1000*C45,0) -> 0 | R45: =IFERROR($O45/1000*D45,0) -> 0 | S45: =IFERROR($O45/1000*E45,0) -> 0 | T45: =IFERROR($O45/1000*F45,0) -> 0 | U45: =IFERROR($O45/1000*G45,0) -> 0 | V45: =IFERROR($O45/1000*H45,0) -> 0 | W45: =IFERROR($O45/1000*I45,0) -> 0 | X45: =IFERROR($O45/1000*J45,0) -> 0 | Y45: =IFERROR($O45/1000*K45,0) -> 0 | AA45: =SUM(Q45:Y45) -> 0
B46: Bio mini tomaten | M46: =SUM(C46:K46) -> 0 | O46: 13.56 | P46: =B46 -> Bio mini tomaten | Q46: =IFERROR($O46/1000*C46,0) -> 0 | R46: =IFERROR($O46/1000*D46,0) -> 0 | S46: =IFERROR($O46/1000*E46,0) -> 0 | T46: =IFERROR($O46/1000*F46,0) -> 0 | U46: =IFERROR($O46/1000*G46,0) -> 0 | V46: =IFERROR($O46/1000*H46,0) -> 0 | W46: =IFERROR($O46/1000*I46,0) -> 0 | X46: =IFERROR($O46/1000*J46,0) -> 0 | Y46: =IFERROR($O46/1000*K46,0) -> 0 | AA46: =SUM(Q46:Y46) -> 0

Sheet Orders

Sheet Desem schema
D2: Starter totaal | E2: Starter per stuk | F2: Aantal stuks besteld
B3: Stockdorf Sourdough | C3: SL(t) | D3: =F3*E3 -> 0 | E3: 170 | F3: =SUMIF(Overview!B3:B11,'Desem schema'!B3,Overview!C3:C11) -> 0
B4: Rye & Wheat Sourdough | C4: LL(r) | D4: =F4*E4 -> 0 | E4: 45 | F4: =SUMIF(Overview!B3:B11,'Desem schema'!B4,Overview!C3:C11) -> 0
B5: Spelt Sourdough | C5: SL(t) | D5: =F5*E5 -> 0 | E5: 65 | F5: =SUMIF(Overview!B1:B9,'Desem schema'!B5,Overview!C1:C9) -> 0
B6: Ciabatta Olive & Origano | C6: SL(t) | D6: =F6*E6 -> 0 | E6: 65 | F6: =SUMIF(Overview!B2:B10,'Desem schema'!B6,Overview!C2:C10) -> 0
B7: Ciabatta Naturale | C7: SL(t) | D7: =F7*E7 -> 0 | E7: 65 | F7: =SUMIF(Overview!B3:B11,'Desem schema'!B7,Overview!C3:C11) -> 0
B8: Brioche | C8: SL(t) | D8: =F8*E8 -> 0 | E8: 15 | F8: =SUMIF(Overview!B3:B11,'Desem schema'!B8,Overview!C3:C11) -> 0
B9: Baguette | C9: SL(t) | D9: =F9*E9 -> 0 | E9: 25 | F9: =SUMIF(Overview!B4:B12,'Desem schema'!B9,Overview!C4:C12) -> 0
C11: Totaal
C12: SL(t) | D12: =SUMIF($C$3:$C$9,C12,$D$3:$D$9) -> 0
C13: LL(r) | D13: =SUMIF($C$3:$C$9,C13,$D$3:$D$9) -> 0
D17: Zondag/woensdag | E17: Maandag/donderdag | F17: Dinsdag/vrijdag
B18: Stiff Levain tarwe | C18: SL(t) | F18: =G18 -> 0 | G18: =$D$12 -> 0 | H18: nodig voor deeg | J18: Totaal SL | K18: =F18 -> 0
F19: =F18/4*2 -> 0 | G19: meel | J19: meel | K19: =(K18-K21)/3*2 -> -40
F20: =F18/4 -> 0 | G20: water | J20: water | K20: =(K18-K21)/3 -> -20
E21: =F21 -> 0 | F21: =F18/4 -> 0 | G21: starter LL | J21: starter LL | K21: 60
E22: =E21/5*2 -> 0 | F22: meel
E23: =E21/5*2 -> 0 | F23: water
D24: =E24 -> 0 | E24: =E21/5 -> 0 | F24: starter LL
D25: =D24/5*2 -> 0 | E25: meel
D26: =D24/5*2 -> 0 | E26: water
D27: =D24/5 -> 0 | E27: starter LL
D30: Zondag/woensdag | E30: Maandag/donderdag | F30: Dinsdag/vrijdag
B31: Liquide Levain rogge | C31: LL(r) | F31: =G31 -> 0 | G31: =$D$13 -> 0 | H31: nodig voor voordeeg | J31: Totaal LL | K31: =F31 -> 0
F32: =F31/5*2 -> 0 | G32: meel | J32: meel | K32: =(K31-K34)/4*2 -> -40
F33: =F31/5*2 -> 0 | G33: water | J33: water | K33: =(K31-K34)/4*2 -> -40
E34: =F34 -> 0 | F34: =F31/5 -> 0 | G34: starter LL | J34: starter LL | K34: 80
E35: =E34/5*2 -> 0 | F35: meel
E36: =E34/5*2 -> 0 | F36: water
D37: =E37 -> 0 | E37: =E34/5 -> 0 | F37: starter LL
D38: =D37/5*2 -> 0 | E38: meel
D39: =D37/5*2 -> 0 | E39: water
D40: =D37/5 -> 0 | E40: starter LL

Sheet Desem schema oud
E1: Op woensdag maken voor donderdag | F1: daarvoor starter nodig | G1: Op donderdag maken voor vrijdag | H1: daarvoor starter nodig | I1: Op vrijdag verwerken in deeg! | K1: Zaterdag
E2: Op zondag maken voor maandag | F2: daarvoor starter nodig | G2: Op maandag maken voor dinsdag | H2: daarvoor starter nodig | I2: Op dinsdag verwerken in deeg! | K2: Woensdag
B3: Brood | M3: aantal | N3: LL/SL totaal
B4: =Overview!B3 -> Brioche | C4: SL | D4: T65/550 | E4: =H4 -> 0 | F4: =E4/4 -> 0 | G4: =I4 -> 0 | H4: =G4/4 -> 0 | I4: =M4*N4 -> 0 | K4: Bakdag | M4: =IF(Overview!C3=0,0,Overview!C3+0.5) -> 0 | N4: 15
B5: =Overview!#REF! -> #REF! | C5: SL | D5: T65/550 | E5: =H5 -> #REF! | F5: =E5/4 -> #REF! | G5: =I5 -> #REF! | H5: =G5/4 -> #REF! | I5: =M5*N5 -> #REF! | K5: Bakdag | M5: =IF(Overview!#REF!=0,0,Overview!#REF!+5) -> #REF! | N5: 10
B6: =Overview!B9 -> Focaccia Naturale | C6: SL | D6: T65/550 | E6: =H6 -> 0 | F6: =E6/4 -> 0 | G6: =I6 -> 0 | H6: =G6/4 -> 0 | I6: =M6*N6 -> 0 | K6: Bakdag | M6: =IF(Overview!C4=0,0,Overview!C4+0.5) -> 0 | N6: 65
B7: =Overview!B4 -> Stockdorf Sourdough | C7: SL | D7: T65/550 | E7: =H7 -> 0 | F7: =E7/4 -> 0 | G7: =I7 -> 0 | H7: =G7/4 -> 0 | I7: =M7*N7 -> 0 | K7: Bakdag | M7: =IF(Overview!C5=0,0,Overview!C5+0.5) -> 0 | N7: 65
B8: =Overview!B10 -> Focaccia Pomodorini | C8: LL | D8: Rogge T85/997 | E8: =H8 -> 0 | F8: =E8/5 -> 0 | G8: =I8 -> 0 | H8: =G8/5 -> 0 | I8: =M8*N8 -> 0 | K8: Bakdag | M8: =IF(Overview!C7=0,0,Overview!C7+0.5) -> 0 | N8: 45
B9: =Overview!B5 -> Spelt Sourdough | C9: SL | D9: T80/1050 | E9: =H9 -> 0 | F9: =E9/4 -> 0 | G9: =I9 -> 0 | H9: =G9/4 -> 0 | I9: =M9*N9 -> 0 | K9: Bakdag | M9: =IF(Overview!C8=0,0,Overview!C8+0.5) -> 0 | N9: 155
B10: =Overview!#REF! -> #REF! | C10: SL | D10: T80/1050 | E10: =H10 -> #REF! | F10: =E10/4 -> #REF! | G10: =I10 -> #REF! | H10: =G10/4 -> #REF! | I10: =M10*N10 -> #REF! | K10: Bakdag | M10: =IF(Overview!#REF!=0,0,Overview!#REF!+0.5) -> #REF! | N10: 110
B11: =Overview!B7 -> Ciabatta Olive & Origano | C11: N/A | D11: N/A
B12: =Overview!B8 -> Ciabatta Naturale | C12: N/A | D12: N/A
B13: =Overview!B11 -> Baguette | C13: SL | D13: T65/550 | E13: =H13 -> 0 | F13: =E13/4 -> 0 | G13: =I13 -> 0 | H13: =G13/4 -> 0 | I13: =M13*N13 -> 0 | K13: Bakdag | M13: =IF(Overview!C11=0,0,Overview!C11+1) -> 0 | N13: 25
B14: =Overview!B12 -> Pizzaballen (10x 252gr) | C14: N/A | D14: N/A
B15: =Overview!B13 -> Focaccia Fulvio (2x 30x40) | C15: N/A | D15: N/A
B16: =Overview!B14 -> Brezen | C16: N/A | D16: N/A
B17: =Overview!B15 -> Baby brioche | C17: SL | D17: T65/550 | E17: =H17 -> 0 | F17: =E17/4 -> 0 | G17: =I17 -> 0 | H17: =G17/4 -> 0 | I17: =M17*N17 -> 0 | K17: Bakdag | M17: =IF(Overview!C15=0,0,Overview!C15+1) -> 0 | N17: 15
B18: =Overview!B16 -> Bagels | C18: N/A | D18: N/A
B19: =Overview!B17 -> Frühstückssemmel | C19: SL | D19: T65/550 | E19: =H19 -> 0 | F19: =E19/4 -> 0 | G19: =I19 -> 0 | H19: =G19/4 -> 0 | I19: =M19*N19 -> 0 | M19: =IF(Overview!C17=0,0,Overview!C17+1) -> 0 | N19: 2
B20: =Overview!B18 -> Blechpizza (abends) (1 blech = 2x 252gr) | C20: N/A | D20: N/A
B23: Total | C23: SL | D23: T65/550 | E23: =H23 -> 0 | F23: =E23/4 -> 0 | G23: =I23 -> 0 | H23: =G23/4 -> 0 | I23: =SUM(I4,I6,I7,I9,I17,I19,I13) -> 0
C24: LL | D24: Rogge T85/997 | E24: =H24 -> 0 | F24: =E24/5 -> 0 | G24: =I24 -> 0 | H24: =G24/5 -> 0 | I24: =I8 -> 0
H28: Totaal check | I28: Totaal | J28: Meel | K28: Desem | L28: Water
C29: =C23 -> SL | D29: =D23 -> T65/550 | H29: =SUM(J29:L29) -> 0 | I29: =G23 -> 0 | J29: =G23/4*2 -> 0 | K29: =G23/4 -> 0 | L29: =G23/4 -> 0
C30: =C24 -> LL | D30: =D24 -> Rogge T85/997 | H30: =SUM(J30:L30) -> 0 | I30: =G24 -> 0 | J30: =G24/5*2 -> 0 | K30: =G24/5 -> 0 | L30: =G24/5*2 -> 0 | N30: =((I29)-N32)/3*2 -> -66.666667 | O30: meel
N31: =((I29)-N32)/3 -> -33.333333 | O31: water
N32: 100 | O32: starter
B33: LL door 5 delen | N33: =SUM(N30:N32) -> 0
B34: SL door 4 delen | J34: water
J35: meel | N35: =250/3 -> 83.333333
J36: starter

Sheet Planning
G1: FRI | H1: FRI | I1: FRI | J1: FRI | K1: FRI | L1: FRI | M1: FRI | N1: FRI | O1: FRI | P1: FRI | Q1: FRI | R1: FRI | S1: FRI | T1: FRI | U1: FRI | V1: FRI | W1: FRI | X1: FRI | Y1: FRI | Z1: FRI | AA1: FRI | AB1: FRI | AC1: FRI | AD1: FRI | AE1: FRI | AF1: FRI | AG1: FRI | AH1: FRI | AI1: FRI | AJ1: FRI | AK1: FRI | AM1: SAT | AN1: SAT | AO1: SAT | AP1: SAT | AQ1: SAT | AR1: SAT | AS1: SAT | AT1: SAT | AU1: SAT | AV1: SAT | AW1: SAT | AX1: SAT | AY1: SAT | AZ1: SAT | BA1: SAT | BB1: SAT | BC1: SAT | BD1: SAT | BE1: SAT | BF1: SAT | BG1: SAT | BH1: SAT | BI1: SAT | BJ1: SAT | BK1: SAT | BL1: SAT | BM1: SAT | BN1: SAT | BO1: SAT | BP1: SAT | BQ1: SAT | BR1: SAT | BS1: SAT | BT1: SAT | BU1: SAT | BV1: SAT | BW1: SAT | BX1: SAT | BY1: SAT | BZ1: SAT | CA1: SAT | CB1: SAT | CC1: SAT | CD1: SAT | CE1: SAT | CF1: SAT | CG1: SAT | CH1: SAT | CI1: SAT | CJ1: SAT | CK1: SAT | CL1: SAT | CM1: SAT | CN1: SAT | CO1: SAT | CP1: SAT | CQ1: SAT | CR1: SAT | CS1: SAT | CT1: SAT | CU1: SAT | CV1: SAT | CW1: SAT | CX1: SAT | CY1: SAT | CZ1: SAT | DA1: SAT | DB1: SAT | DC1: SAT | DD1: SAT | DE1: SAT | DF1: SAT | DG1: SAT | DH1: SAT | DI1: SAT | DJ1: SAT | DK1: SAT | DL1: SAT | DM1: SAT | DN1: SAT | DO1: SAT | DP1: SAT | DQ1: SAT | DR1: SAT | DS1: SAT | DT1: SAT | DU1: SAT | DV1: SAT | DW1: SAT | DX1: SAT | DY1: SAT | DZ1: SAT | EA1: SAT | EB1: SAT | EC1: SAT | ED1: SAT | EE1: SAT | EF1: SAT | EG1: SAT | EI1: SUN | EJ1: SUN | EK1: SUN | EL1: SUN | EM1: SUN | EN1: SUN | EO1: SUN | EP1: SUN | EQ1: SUN | ER1: SUN | ES1: SUN | ET1: SUN | EU1: SUN | EV1: SUN | EW1: SUN | EX1: SUN | EY1: SUN | EZ1: SUN | FA1: SUN | FB1: SUN | FC1: SUN | FD1: SUN | FE1: SUN | FF1: SUN | FG1: SUN | FH1: SUN | FI1: SUN | FJ1: SUN | FK1: SUN | FL1: SUN | FM1: SUN | FN1: SUN | FO1: SUN | FP1: SUN | FQ1: SUN | FR1: SUN | FS1: SUN
G2: 16 | H2: =G2+0.15 -> 16.15 | I2: =H2+0.15 -> 16.3 | J2: =I2+0.15 -> 16.45 | K2: 17 | L2: =K2+0.15 -> 17.15 | M2: =L2+0.15 -> 17.3 | N2: =M2+0.15 -> 17.45 | O2: 18 | P2: =O2+0.15 -> 18.15 | Q2: =P2+0.15 -> 18.3 | R2: =Q2+0.15 -> 18.45 | S2: 19 | T2: =S2+0.15 -> 19.15 | U2: =T2+0.15 -> 19.3 | V2: =U2+0.15 -> 19.45 | W2: 20 | X2: =W2+0.15 -> 20.15 | Y2: =X2+0.15 -> 20.3 | Z2: =Y2+0.15 -> 20.45 | AA2: 21 | AB2: =AA2+0.15 -> 21.15 | AC2: =AB2+0.15 -> 21.3 | AD2: =AC2+0.15 -> 21.45 | AE2: 22 | AF2: =AE2+0.15 -> 22.15 | AG2: =AF2+0.15 -> 22.3 | AH2: =AG2+0.15 -> 22.45 | AI2: 23 | AJ2: =AI2+0.15 -> 23.15 | AK2: =AJ2+0.15 -> 23.3 | AL2: =AK2+0.15 -> 23.45 | AM2: 24 | AN2: =AM2+0.15 -> 24.15 | AO2: =AN2+0.15 -> 24.3 | AP2: =AO2+0.15 -> 24.45 | AQ2: 1 | AR2: =AQ2+0.15 -> 1.15 | AS2: =AR2+0.15 -> 1.3 | AT2: =AS2+0.15 -> 1.45 | AU2: 2 | AV2: =AU2+0.15 -> 2.15 | AW2: =AV2+0.15 -> 2.3 | AX2: =AW2+0.15 -> 2.45 | AY2: 3 | AZ2: =AY2+0.15 -> 3.15 | BA2: =AZ2+0.15 -> 3.3 | BB2: =BA2+0.15 -> 3.45 | BC2: 4 | BD2: =BC2+0.15 -> 4.15 | BE2: =BD2+0.15 -> 4.3 | BF2: =BE2+0.15 -> 4.45 | BG2: 5 | BH2: =BG2+0.15 -> 5.15 | BI2: =BH2+0.15 -> 5.3 | BJ2: =BI2+0.15 -> 5.45 | BK2: 6 | BL2: =BK2+0.15 -> 6.15 | BM2: =BL2+0.15 -> 6.3 | BN2: =BM2+0.15 -> 6.45 | BO2: 7 | BP2: =BO2+0.15 -> 7.15 | BQ2: =BP2+0.15 -> 7.3 | BR2: =BQ2+0.15 -> 7.45 | BS2: 8 | BT2: =BS2+0.15 -> 8.15 | BU2: =BT2+0.15 -> 8.3 | BV2: =BU2+0.15 -> 8.45 | BW2: 9 | BX2: =BW2+0.15 -> 9.15 | BY2: =BX2+0.15 -> 9.3 | BZ2: =BY2+0.15 -> 9.45 | CA2: 10 | CB2: =CA2+0.15 -> 10.15 | CC2: =CB2+0.15 -> 10.3 | CD2: =CC2+0.15 -> 10.45 | CE2: 11 | CF2: =CE2+0.15 -> 11.15 | CG2: =CF2+0.15 -> 11.3 | CH2: =CG2+0.15 -> 11.45 | CI2: 12 | CJ2: =CI2+0.15 -> 12.15 | CK2: =CJ2+0.15 -> 12.3 | CL2: =CK2+0.15 -> 12.45 | CM2: 13 | CN2: =CM2+0.15 -> 13.15 | CO2: =CN2+0.15 -> 13.3 | CP2: =CO2+0.15 -> 13.45 | CQ2: 14 | CR2: =CQ2+0.15 -> 14.15 | CS2: =CR2+0.15 -> 14.3 | CT2: =CS2+0.15 -> 14.45 | CU2: 15 | CV2: =CU2+0.15 -> 15.15 | CW2: =CV2+0.15 -> 15.3 | CX2: =CW2+0.15 -> 15.45 | CY2: 16 | CZ2: =CY2+0.15 -> 16.15 | DA2: =CZ2+0.15 -> 16.3 | DB2: =DA2+0.15 -> 16.45 | DC2: 17 | DD2: =DC2+0.15 -> 17.15 | DE2: =DD2+0.15 -> 17.3 | DF2: =DE2+0.15 -> 17.45 | DG2: 18 | DH2: =DG2+0.15 -> 18.15 | DI2: =DH2+0.15 -> 18.3 | DJ2: =DI2+0.15 -> 18.45 | DK2: 19 | DL2: =DK2+0.15 -> 19.15 | DM2: =DL2+0.15 -> 19.3 | DN2: =DM2+0.15 -> 19.45 | DO2: 20 | DP2: =DO2+0.15 -> 20.15 | DQ2: =DP2+0.15 -> 20.3 | DR2: =DQ2+0.15 -> 20.45 | DS2: 21 | DT2: =DS2+0.15 -> 21.15 | DU2: =DT2+0.15 -> 21.3 | DV2: =DU2+0.15 -> 21.45 | DW2: 22 | DX2: =DW2+0.15 -> 22.15 | DY2: =DX2+0.15 -> 22.3 | DZ2: =DY2+0.15 -> 22.45 | EA2: 23 | EB2: =EA2+0.15 -> 23.15 | EC2: =EB2+0.15 -> 23.3 | ED2: =EC2+0.15 -> 23.45 | EE2: 24 | EF2: =EE2+0.15 -> 24.15 | EG2: =EF2+0.15 -> 24.3 | EH2: =EG2+0.15 -> 24.45 | EI2: 1 | EJ2: =EI2+0.15 -> 1.15 | EK2: =EJ2+0.15 -> 1.3 | EL2: =EK2+0.15 -> 1.45 | EM2: 2 | EN2: =EM2+0.15 -> 2.15 | EO2: =EN2+0.15 -> 2.3 | EP2: =EO2+0.15 -> 2.45 | EQ2: 3 | ER2: =EQ2+0.15 -> 3.15 | ES2: =ER2+0.15 -> 3.3 | ET2: =ES2+0.15 -> 3.45 | EU2: 4 | EV2: =EU2+0.15 -> 4.15 | EW2: =EV2+0.15 -> 4.3 | EX2: =EW2+0.15 -> 4.45 | EY2: 5 | EZ2: =EY2+0.15 -> 5.15 | FA2: =EZ2+0.15 -> 5.3 | FB2: =FA2+0.15 -> 5.45 | FC2: 6 | FD2: =FC2+0.15 -> 6.15 | FE2: =FD2+0.15 -> 6.3 | FF2: =FE2+0.15 -> 6.45 | FG2: 7 | FH2: =FG2+0.15 -> 7.15 | FI2: =FH2+0.15 -> 7.3 | FJ2: =FI2+0.15 -> 7.45 | FK2: 8 | FL2: =FK2+0.15 -> 8.15 | FM2: =FL2+0.15 -> 8.3 | FN2: =FM2+0.15 -> 8.45 | FO2: 9 | FP2: =FO2+0.15 -> 9.15 | FQ2: =FP2+0.15 -> 9.3 | FR2: =FQ2+0.15 -> 9.45 | FS2: 10
A3: Datum | C3: 45982
C4: Start | D4: Dauer in St.
B5: {=_xlfn.SWITCH(WEEKDAY(($C$3+C5),2),1,"MO",2,"DI",3,"MI",4,"DO",5,"FR",6,"SA",7,"SO")} -> FR | C5: 0.79166667 | D5: 0.010416667
B6: {=_xlfn.SWITCH(WEEKDAY(($C$3+C6),2),1,"MO",2,"DI",3,"MI",4,"DO",5,"FR",6,"SA",7,"SO")} -> FR | C6: =C5+D5 -> 0.80208333 | D6: 0.83333333 | E6: 14-20 uur (een nacht)
B7: {=_xlfn.SWITCH(WEEKDAY(($C$3+C7),2),1,"MO",2,"DI",3,"MI",4,"DO",5,"FR",6,"SA",7,"SO")} -> SA | C7: =C6+D6 -> 1.6354167 | D7: 0.013888889
B8: {=_xlfn.SWITCH(WEEKDAY(($C$3+C8),2),1,"MO",2,"DI",3,"MI",4,"DO",5,"FR",6,"SA",7,"SO")} -> SA | C8: =C7+D7 -> 1.6493056 | D8: 0.034722222
B9: {=_xlfn.SWITCH(WEEKDAY(($C$3+C9),2),1,"MO",2,"DI",3,"MI",4,"DO",5,"FR",6,"SA",7,"SO")} -> SA | C9: =C8+D8 -> 1.6840278 | D9: 0.03125
B10: {=_xlfn.SWITCH(WEEKDAY(($C$3+C10),2),1,"MO",2,"DI",3,"MI",4,"DO",5,"FR",6,"SA",7,"SO")} -> SA | C10: =C9+D9 -> 1.7152778 | D10: 0.020833333
A11: Fertig! Bon appétit. | B11: {=_xlfn.SWITCH(WEEKDAY(($C$3+C11),2),1,"MO",2,"DI",3,"MI",4,"DO",5,"FR",6,"SA",7,"SO")} -> SA | C11: =C10+D10 -> 1.7361111
A13: Datum | C13: 45982
C14: Start | D14: Dauer in St.
B15: {=_xlfn.SWITCH(WEEKDAY(($C$13+C15),2),1,"MO",2,"DI",3,"MI",4,"DO",5,"FR",6,"SA",7,"SO")} -> FR | C15: 0.83333333 | D15: 0.010416667
B16: {=_xlfn.SWITCH(WEEKDAY(($C$13+C16),2),1,"MO",2,"DI",3,"MI",4,"DO",5,"FR",6,"SA",7,"SO")} -> FR | C16: =C15+D15 -> 0.84375 | D16: 0.03125
B17: {=_xlfn.SWITCH(WEEKDAY(($C$13+C17),2),1,"MO",2,"DI",3,"MI",4,"DO",5,"FR",6,"SA",7,"SO")} -> FR | C17: =C16+D16 -> 0.875 | D17: 0.03125
B18: {=_xlfn.SWITCH(WEEKDAY(($C$13+C18),2),1,"MO",2,"DI",3,"MI",4,"DO",5,"FR",6,"SA",7,"SO")} -> FR | C18: =C17+D17 -> 0.90625 | D18: 0.0625
B19: {=_xlfn.SWITCH(WEEKDAY(($C$13+C19),2),1,"MO",2,"DI",3,"MI",4,"DO",5,"FR",6,"SA",7,"SO")} -> FR | C19: =C18+D18 -> 0.96875 | D19: 0.017361111
B20: {=_xlfn.SWITCH(WEEKDAY(($C$13+C20),2),1,"MO",2,"DI",3,"MI",4,"DO",5,"FR",6,"SA",7,"SO")} -> FR | C20: =C19+D19 -> 0.98611111 | D20: 0.83333333 | E20: 14-20 uur (een nacht)
B21: {=_xlfn.SWITCH(WEEKDAY(($C$13+C21),2),1,"MO",2,"DI",3,"MI",4,"DO",5,"FR",6,"SA",7,"SO")} -> SA | C21: =C20+D20 -> 1.8194444 | D21: 0.03125
A22: Fertig! Bon appétit. | B22: {=_xlfn.SWITCH(WEEKDAY(($C$13+C22),2),1,"MO",2,"DI",3,"MI",4,"DO",5,"FR",6,"SA",7,"SO")} -> SA | C22: =C21+D21 -> 1.8506944
A24: Datum | C24: 45983
C25: Start | D25: Dauer in St.
B26: {=_xlfn.SWITCH(WEEKDAY(($C$24+C26),2),1,"MO",2,"DI",3,"MI",4,"DO",5,"FR",6,"SA",7,"SO")} -> SA | C26: 0.375 | D26: 0.041666667
B27: {=_xlfn.SWITCH(WEEKDAY(($C$24+C27),2),1,"MO",2,"DI",3,"MI",4,"DO",5,"FR",6,"SA",7,"SO")} -> SA | C27: =C26+D26 -> 0.41666667 | D27: 0.0625
B28: {=_xlfn.SWITCH(WEEKDAY(($C$24+C28),2),1,"MO",2,"DI",3,"MI",4,"DO",5,"FR",6,"SA",7,"SO")} -> SA | C28: =C27+D27 -> 0.47916667 | D28: 0.0625
B29: {=_xlfn.SWITCH(WEEKDAY(($C$24+C29),2),1,"MO",2,"DI",3,"MI",4,"DO",5,"FR",6,"SA",7,"SO")} -> SA | C29: =C28+D28 -> 0.54166667 | D29: 0.024305556
B30: {=_xlfn.SWITCH(WEEKDAY(($C$24+C30),2),1,"MO",2,"DI",3,"MI",4,"DO",5,"FR",6,"SA",7,"SO")} -> SA | C30: =C29+D29 -> 0.56597222 | D30: 0.64236111 | E30: 14-20 uur (een nacht)
B31: {=_xlfn.SWITCH(WEEKDAY(($C$24+C31),2),1,"MO",2,"DI",3,"MI",4,"DO",5,"FR",6,"SA",7,"SO")} -> SO | C31: =C30+D30 -> 1.2083333 | D31: 0.024305556
A32: Fertig! Bon appétit. | B32: {=_xlfn.SWITCH(WEEKDAY(($C$24+C32),2),1,"MO",2,"DI",3,"MI",4,"DO",5,"FR",6,"SA",7,"SO")} -> SO | C32: =C31+D31 -> 1.2326389
A34: Datum | C34: 45983
C35: Start | D35: Dauer in St.
B36: {=_xlfn.SWITCH(WEEKDAY(($C$34+C36),2),1,"MO",2,"DI",3,"MI",4,"DO",5,"FR",6,"SA",7,"SO")} -> SA | C36: 0.43055556 | D36: 0.027777778
B37: {=_xlfn.SWITCH(WEEKDAY(($C$34+C37),2),1,"MO",2,"DI",3,"MI",4,"DO",5,"FR",6,"SA",7,"SO")} -> SA | C37: =C36+D36 -> 0.45833333 | D37: 0.020833333
B38: {=_xlfn.SWITCH(WEEKDAY(($C$34+C38),2),1,"MO",2,"DI",3,"MI",4,"DO",5,"FR",6,"SA",7,"SO")} -> SA | C38: =C37+D37 -> 0.47916667 | D38: 0.020833333
B39: {=_xlfn.SWITCH(WEEKDAY(($C$34+C39),2),1,"MO",2,"DI",3,"MI",4,"DO",5,"FR",6,"SA",7,"SO")} -> SA | C39: =C38+D38 -> 0.5 | D39: 0.020833333
B40: {=_xlfn.SWITCH(WEEKDAY(($C$34+C40),2),1,"MO",2,"DI",3,"MI",4,"DO",5,"FR",6,"SA",7,"SO")} -> SA | C40: =C39+D39 -> 0.52083333 | D40: 0.020833333
B41: {=_xlfn.SWITCH(WEEKDAY(($C$34+C41),2),1,"MO",2,"DI",3,"MI",4,"DO",5,"FR",6,"SA",7,"SO")} -> SA | C41: =C40+D40 -> 0.54166667 | D41: 0.020833333
B42: {=_xlfn.SWITCH(WEEKDAY(($C$34+C42),2),1,"MO",2,"DI",3,"MI",4,"DO",5,"FR",6,"SA",7,"SO")} -> SA | C42: =C41+D41 -> 0.5625 | D42: 0.020833333
B43: {=_xlfn.SWITCH(WEEKDAY(($C$34+C43),2),1,"MO",2,"DI",3,"MI",4,"DO",5,"FR",6,"SA",7,"SO")} -> SA | C43: =C42+D42 -> 0.58333333 | D43: 0.041666667
...

Sheet Planning 
G1: Echte tijd
B2: Produkt | C2: Wat | D2: WE | E2: Start | F2: Duur | G2: Gedaan | H2: Te doen | K2: Wie | L2: Wat | M2: 46098 | N2: Start | O2: Duur | P2: mogelijke duur
B3: Stockdorf SD | C3: Deeg mengen, kneden | D3: TU | E3: 0.27083333 | F3: 0.013888889 | K3: Wheat & Rye | L3: Voordeeg mengen & rijzen | M3: {=_xlfn.SWITCH(WEEKDAY(($M$2+N3),2),1,"MO",2,"TU",3,"WE",4,"TH",5,"FR",6,"SA",7,"SO")} -> TU | N3: 0.25 | O3: 0.54166667 | P3: 12-16 uur
B4: Stockdorf SD | C4: Start bulkrijs (180min) | D4: TU | E4: 0.29166667 | F4: 0.03125 | K4: Wheat & Rye | L4: Deeg mengen, kneden | M4: {=_xlfn.SWITCH(WEEKDAY(($M$2+N4),2),1,"MO",2,"TU",3,"WE",4,"TH",5,"FR",6,"SA",7,"SO")} -> TU | N4: =N3+O3 -> 0.79166667 | O4: 0.010416667
B5: Stockdorf SD | C5: Vouwen 1@45 | D5: TU | E5: 0.32291667 | F5: 0.03125 | K5: Wheat & Rye | L5: Start bulkrijs (30min) | M5: {=_xlfn.SWITCH(WEEKDAY(($M$2+N5),2),1,"MO",2,"TU",3,"WE",4,"TH",5,"FR",6,"SA",7,"SO")} -> TU | N5: =N4+O4 -> 0.80208333 | O5: 0.020833333
B6: Stockdorf SD | C6: Vouwen 1@90, rest bulkrijs | D6: TU | E6: 0.35416667 | F6: 0.0625 | K6: Wheat & Rye | L6: Verdelen, vormen | M6: {=_xlfn.SWITCH(WEEKDAY(($M$2+N6),2),1,"MO",2,"TU",3,"WE",4,"TH",5,"FR",6,"SA",7,"SO")} -> TU | N6: =N5+O5 -> 0.82291667 | O6: 0.0069444444
B7: Stockdorf SD | C7: Verdelen, vormen | D7: TU | E7: 0.41666667 | F7: 0.020833333 | K7: Wheat & Rye | L7: Start narijs (koel overnacht) | M7: {=_xlfn.SWITCH(WEEKDAY(($M$2+N7),2),1,"MO",2,"TU",3,"WE",4,"TH",5,"FR",6,"SA",7,"SO")} -> TU | N7: =N6+O6 -> 0.82986111 | O7: 0.37847222
B8: Stockdorf SD | C8: Start vormijs (25min) | D8: TU | E8: 0.4375 | F8: 0.017361111 | K8: Wheat & Rye | L8: Bakken (250->210°C, 55min) | M8: {=_xlfn.SWITCH(WEEKDAY(($M$2+N8),2),1,"MO",2,"TU",3,"WE",4,"TH",5,"FR",6,"SA",7,"SO")} -> WE | N8: =N7+O7 -> 1.2083333 | O8: 0.041666667
B9: Stockdorf SD | C9: Start narijs (koel overnacht) | D9: TU | E9: 0.45486111 | F9: 0.4375 | K9: Wheat & Rye | L9: Klaar! | M9: {=_xlfn.SWITCH(WEEKDAY(($M$2+N9),2),1,"MO",2,"TU",3,"WE",4,"TH",5,"FR",6,"SA",7,"SO")} -> WE | N9: =N8+O8 -> 1.25
B10: Baguette trad. | C10: VB, mengen | D10: TU | E10: 0.52083333 | F10: 0.020833333 | K10: Stockdorf SD | L10: Zadenmelange voorbereiden | M10: {=_xlfn.SWITCH(WEEKDAY(($M$2+N10),2),1,"MO",2,"TU",3,"WE",4,"TH",5,"FR",6,"SA",7,"SO")} -> TU | N10: 0.3125 | O10: 0.017361111
B11: Ciabatta | C11: VB, mengen | D11: TU | E11: 0.52083333 | F11: 0.020833333 | K11: Stockdorf SD | L11: Deeg mengen, kneden | M11: {=_xlfn.SWITCH(WEEKDAY(($M$2+N11),2),1,"MO",2,"TU",3,"WE",4,"TH",5,"FR",6,"SA",7,"SO")} -> TU | N11: 0.5 | O11: 0.013888889
B12: Baguette trad. | C12: Start autolyse (60min) | D12: TU | E12: 0.54166667 | F12: 0.041666667 | K12: Stockdorf SD | L12: Start bulkrijs (180min) | M12: {=_xlfn.SWITCH(WEEKDAY(($M$2+N12),2),1,"MO",2,"TU",3,"WE",4,"TH",5,"FR",6,"SA",7,"SO")} -> TU | N12: =N11+O11 -> 0.51388889 | O12: 0.03125
B13: Ciabatta | C13: Start autolyse (60min) | D13: TU | E13: 0.54166667 | F13: 0.041666667 | K13: Stockdorf SD | L13: Vouwen 1@45 | M13: {=_xlfn.SWITCH(WEEKDAY(($M$2+N13),2),1,"MO",2,"TU",3,"WE",4,"TH",5,"FR",6,"SA",7,"SO")} -> TU | N13: =N12+O12 -> 0.54513889 | O13: 0.03125
B14: Ciabatta | C14: Evt. vulling voorbereiden | D14: TU | E14: 0.54513889 | F14: 0.0069444444 | K14: Stockdorf SD | L14: Vouwen 1@90, rest bulkrijs | M14: {=_xlfn.SWITCH(WEEKDAY(($M$2+N14),2),1,"MO",2,"TU",3,"WE",4,"TH",5,"FR",6,"SA",7,"SO")} -> TU | N14: =N13+O13 -> 0.57638889 | O14: 0.0625
B15: Baguette trad. | C15: Deeg voor CB uit kneder | D15: TU | E15: 0.57638889 | F15: 0.0069444444 | K15: Stockdorf SD | L15: Verdelen, vormen | M15: {=_xlfn.SWITCH(WEEKDAY(($M$2+N15),2),1,"MO",2,"TU",3,"WE",4,"TH",5,"FR",6,"SA",7,"SO")} -> TU | N15: =N14+O14 -> 0.63888889 | O15: 0.010416667
B16: Baguette trad. | C16: Mengen & kneden | D16: TU | E16: 0.58333333 | F16: 0.020833333 | K16: Stockdorf SD | L16: Start vormijs (25min) | M16: {=_xlfn.SWITCH(WEEKDAY(($M$2+N16),2),1,"MO",2,"TU",3,"WE",4,"TH",5,"FR",6,"SA",7,"SO")} -> TU | N16: =N15+O15 -> 0.64930556 | O16: 0.017361111
B17: Baguette trad. | C17: Start bulkrijs (40min) | D17: TU | E17: 0.60416667 | F17: 0.013888889 | K17: Stockdorf SD | L17: Start narijs (koel overnacht) | M17: {=_xlfn.SWITCH(WEEKDAY(($M$2+N17),2),1,"MO",2,"TU",3,"WE",4,"TH",5,"FR",6,"SA",7,"SO")} -> TU | N17: =N16+O16 -> 0.66666667 | O17: 0.625 | P17: 16-20 uur
B18: Ciabatta | C18: Deeg terug in kneder, mengen, kneden, inwas | D18: TU | E18: 0.60486111 | F18: 0.020833333 | K18: Stockdorf SD | L18: Bakken (225°C, 45min) | M18: {=_xlfn.SWITCH(WEEKDAY(($M$2+N18),2),1,"MO",2,"TU",3,"WE",4,"TH",5,"FR",6,"SA",7,"SO")} -> WE | N18: =N17+O17 -> 1.2916667 | O18: 0.03125
